Workbook
Name _zz8: #REF!
Name _zz8: #REF!
Name ABCcostPerLine: #REF!
Name ABCcostPerLine: #REF!
Name ABCcostPerLine: #REF!
Name ABCcostPerLine: #REF!
Name ABClinesMax: #REF!
Name ABClinesMax: #REF!
Name ABClinesMax: #REF!
Name ABClinesMax: #REF!
Name ABClinesMin: #REF!
Name ABClinesMin: #REF!
Name ABClinesMin: #REF!
Name ABClinesMin: #REF!
Name ABCterminalCost: #REF!
Name ABCterminalCost: #REF!
Name ABCterminalCost: #REF!
Name ABCterminalCost: #REF!
Name ABCutil: #REF!
Name ABCutil: #REF!
Name ABCutil: #REF!
Name ABCutil: #REF!
Name AccessNodeSize: #REF!
Name AccessNodeSize: #REF!
Name AccessNodeSize: #REF!
Name AccessNodeSize: #REF!
Name ActCabinetTelcoCost: #REF!
Name ActCabinetTelcoCost: #REF!
Name ActCabinetTelcoCost: #REF!
Name ActCabinetTelcoCost: #REF!
Name ActCabinetVideoCost: #REF!
Name ActCabinetVideoCost: #REF!
Name ActCabinetVideoCost: #REF!
Name ActCabinetVideoCost: #REF!
Name ActiveLines: #REF!
Name ActiveLines: #REF!
Name ActiveLines: #REF!
Name ActiveLines: #REF!
Name ActiveUtil: #REF!
Name ActiveUtil: #REF!
Name ActiveUtil: #REF!
Name ActiveUtil: #REF!
Name AreaPerEmployee: #REF!
Name AreaPerEmployee: #REF!
Name AreaPerEmployee: #REF!
Name AreaPerEmployee: #REF!
Name AreaPerHeadend: #REF!
Name AreaPerHeadend: #REF!
Name AreaPerHeadend: #REF!
Name AreaPerHeadend: #REF!
Name AreaPerSwitch: #REF!
Name AreaPerSwitch: #REF!
Name AreaPerSwitch: #REF!
Name AreaPerSwitch: #REF!
Name ArialCoaxLabor: #REF!
Name ArialCoaxLabor: #REF!
Name ArialCoaxLabor: #REF!
Name ArialCoaxLabor: #REF!
Name ArialCoaxMaterial: #REF!
Name ArialCoaxMaterial: #REF!

Sheet Sommaire
A1: SANCY - SLP | C1: 46022
A2: Méthode de comptabilisation des intérêts | B2: Coupon couru
A5: Particularités du FPCI
A8: Fonds investi
A10: Périodicité de la VL | B10: Trimestrielle
A12: Date de constitution | B12: 44825
A14: Date de clôture du premier exercice comptable | B14: 44926
A16: Type de parts
A17: Parts A
A18: Commandité
A19: Valeur nominale des parts
A20: Parts A
A21: Commandité
A23: Frais de gestion | B23: N/A
A25: Frais dépositaire | B25: Caceis
A27: Frais commissaire aux comptes | B27: Deloitte
A30: Evaluation des OPC | B30: dernière VL connue
A32: Devise de comptabilisation | B32: Euro
A34: Zone de saisie
A37: Onglets | B37: Synthèse des contrôles
A38: Inventaire | B38: =Inventaire!F13
A39: Calcul VL | B39: ='Calcul VL'!F6 -> OK
A40: OD Rééval | B40: =IF(AND('O.D Rééval'!G43="OK",'O.D Rééval'!G86="OK",'O.D Rééval'!G127="OK"),"OK","Anomalies") -> OK
A41: Int courus OC | B41: ='Intérêts OC'!L22 -> OK
A42: Rappro titres | B42: ='Rappro Titres & Parts'!C20 -> OK
B43: ='Rappro Titres & Parts'!F18 -> OK
B44: ='Rappro Titres & Parts'!I18 -> OK
A45: PVMV | B45: =PVMV!O29 -> OK
A46: Liste porteurs selon versement | B46: ='Liste porteurs selon versement '!D32 -> OK
B47: ='Liste porteurs selon versement '!D32 -> OK
A48: Frais de gestion | B48: ='Frais de gestion'!H112 -> OK
A49: Bilan | B49: =Bilan!I100 -> OK
A50: N-1 | B50: =Bilan!J100 -> OK
A51: Résultat | B51: =Résultat!H193 -> OK
A52: N-1 | B52: =Résultat!I193 -> OK
A53: Var actif net après valorisation | B53: =IF(B38="",'Capitaux propres'!D36,"") -> OK
A54: Var actif net avant valorisation | B54: =IF(B38="","",'Capitaux propres'!D39)
A55: N-1 | B55: ='Capitaux propres'!E36 -> OK
A56: Rappro banque | B56: ='Rappro Banque'!C13 -> OK
A57: rapprobalance | B57: ='Rappro Balance'!E33 -> OK
...

Sheet Inventaire
B1: =Sommaire!A1 -> SANCY - SLP | G1: Inventaire au : | H1: =Sommaire!C1 -> 46022
B2: Code isin bdf | C2: FR001400CQD5
C3: FR001400CQE3
B7: Actif net : | C7: =D44 -> 11465750 | D7: Type de parts : | E7: Total | F7: Parts A1 | G7: Parts de Commandité
D8: Nbre de parts : | E8: =SUM(F8:I8) -> 15380.56 | F8: =+'Calcul VL'!C9 -> 15379.56 | G8: =+'Calcul VL'!C10 -> 1
D9: valeur liquidative : | F9: ='Calcul VL'!E9 -> 745.47027 | G9: ='Calcul VL'!E10 -> 745.47027
A12: G ou I | B12: Code Titre | C12: Libellé | D12: Quantité | E12: Prix de revient unitaire | F12: Estimation unitaire | G12: Origine du cours | H12: Prix de revient | I12: Intérêts capitalisés | J12: Prix de revient global | K12: Valeur d'estimation hors coupon | L12: +/- value potentielle | M12: Coupon couru | N12: Valeur d'estimation coupon inclus | O12: % actif net | Q12: Valeur totale de la participation | R12: Ecart | S12: Cours unitaire de valorisation
B13: FONDS GENERAL | F13: =IF(ABS('Rappro Balance'!$G$22)>0.009,"ANOMALIE DE VALORISATION","")
B14: Instruments financiers de capital Investissement
A16: G | B16: FRACEUR00294 | C16: =PVMV!B15 -> Heka Invest - Actions | D16: =+PVMV!E15 -> 14423076 | E16: =PVMV!N15 -> 1.04 | F16: 0.78809726 | G16: =H1 -> 46022 | H16: =PVMV!M15 -> 14999999 | J16: =+I16+H16 -> 14999999 | K16: =D16*F16 -> 11366787 | L16: =ROUND(K16-J16,2) -> -3633212.3 | N16: =ROUND(+M16+K16,2) -> 11366787 | O16: =+N16/$D$44*100 -> 99.136877 | Q16: 11366787 | R16: =Q16-N16 -> 0.0047987998 | S16: =Q16/D16 -> 0.78809726
B18: Total | H18: =SUM(H16:H17) -> 14999999 | I18: =SUM(I16:I17) -> 0 | J18: =SUM(J16:J17) -> 14999999 | K18: =SUM(K16:K17) -> 11366787 | L18: =SUM(L16:L17) -> -3633212.3 | M18: =SUM(M16:M17) -> 0 | N18: =SUM(N16:N17) -> 11366787 | O18: =SUM(O15:O17) -> 99.136877
B19: Autres instruments financiers
A21: I | O21: =+N21/$D$44*100 -> 0
A22: I | O22: =+N22/$D$44*100 -> 0
C24: Total | H24: =SUM(H21:H22) -> 0 | I24: =SUM(I21:I22) -> 0 | J24: =SUM(J21:J22) -> 0 | K24: =SUM(K21:K22) -> 0 | L24: =SUM(L21:L22) -> 0 | N24: =SUM(N21:N22) -> 0 | O24: =SUM(O19:O22) -> 0
C27: Total fonds général | H27: =+H18+H24 -> 14999999 | I27: =+I18+I24 -> 0 | J27: =+J18+J24 -> 14999999 | K27: =+K18+K24 -> 11366787 | L27: =+L18+L24 -> -3633212.3 | M27: =+M18+M24 -> 0 | N27: =ROUND(+N18+N24,2) -> 11366787 | O27: =+O18+O24 -> 99.136877
B30: Total inventaire : | H30: =H27 -> 14999999 | I30: =I27 -> 0 | J30: =J27 -> 14999999 | K30: =K27 -> 11366787 | L30: =L27 -> -3633212.3 | M30: =M27 -> 0 | N30: =N27 -> 11366787 | O30: =+O27 -> 99.136877
B32: Composition de l'actif net | D32: Fonds général | E32: %
B34: Inventaire | D34: =+N30 -> 11366787 | E34: =+D34/$D$44*100 -> 99.136877
B36: Disponibilités | D36: ='Rappro Banque'!C17 -> 109211.49 | E36: =+D36/$D$44*100 -> 0.95250191
B38: Créances | D38: =+'Créances_&_dettes'!G13 -> 0 | E38: =+D38/$D$44*100 -> 0
B40: Dettes | D40: =-+'Créances_&_dettes'!G59 -> -10248 | E40: =+D40/$D$44*100 -> -0.089379237
B42: Dettes financières | D42: =-(Emprunt!K68+Emprunt!K69) -> 0 | E42: =+D42/$D$44*100 -> 0
B44: Actif net | D44: =ROUNDDOWN(SUM(D34:D43),2) -> 11465750 | E44: =SUM(E33:E43) -> 100
B47: BDF : complément Composition de l'actif net | D47: Fonds général | E47: Reemploi/Compte bloqué/Clawback | F47: Reinvestissement | G47: Total | H47: %
B49: Inventaire BDF | D49: =D34 -> 11366787 | G49: =D49+E49+F49 -> 11366787 | H49: =+G49/$G$59 -> 0.99136877
B51: Disponibilité BDF | D51: =D36 -> 109211.49 | G51: =D51+E51+F51 -> 109211.49 | H51: =+G51/$G$59 -> 0.0095250191
B53: Créances BDF | D53: =D38 -> 0 | G53: =D53+E53+F53 -> 0 | H53: =+G53/$G$59 -> 0
B55: Dettes BDF | D55: =D40 -> -10248 | G55: =D55+E55+F55 -> -10248 | H55: =+G55/$G$59 -> -0.00089379237
B57: Dettes financières BDF | D57: =D42 -> 0 | G57: =D57+E57+F57 -> 0 | H57: =+G57/$G$59 -> 0
B59: Actif net BDF | D59: =ROUNDDOWN(SUM(D48:D58),2) -> 11465750 | E59: =ROUNDDOWN(SUM(E48:E58),2) -> 0 | F59: =ROUNDDOWN(SUM(F48:F58),2) -> 0 | G59: =ROUNDDOWN(SUM(G48:G58),2) -> 11465750 | H59: =SUM(H48:H58) -> 1
E62: Contrôle: | F62: =IF((D44-G59)=0,"OK","Anomalies") -> OK

Sheet Calcul VL
B1: =+Inventaire!B1 -> SANCY - SLP | D1: Calcul des valeurs liquidatives : | F1: =+Inventaire!H1 -> 46022
B4: Actif net | D4: =Inventaire!C7 -> 11465750
F6: =IF(F7=0,"OK","Anomalie") -> OK
B7: Type de parts | C7: Nombre de parts | D7: Actif net réparti | E7: VL | F7: =D4-D12 -> 0 | H7: Valeur liquidative recalculée | I7: Ecart non affectable | J7: Vérification | K7: SI l'écart divisé par le nombre de parts est inférieur à 0,01= OK
A9: FR001400CQD5 | B9: Parts A | C9: 15379.56 | D9: =$D$4*C9/$C$12 -> 11465005 | E9: =ROUNDDOWN(D9/C9,6) -> 745.47027 | H9: =E9*C9 -> 11465005 | I9: =D9-H9 -> 0.014808957 | J9: =+I9/C9/100 -> 9.6289858e-09 | K9: =IF(J9>0.01,"'ANOMALIE","'OK") -> 'OK
A10: FR001400CQE3 | B10: Part de commandité | C10: 1 | D10: =$D$4*C10/$C$12 -> 745.47027 | E10: =ROUNDDOWN(D10/C10,6) -> 745.47027 | H10: =E10*C10 -> 745.47027 | I10: =D10-H10 -> 9.6289853e-07 | J10: =+I10/C10/100 -> 9.6289853e-09 | K10: =IF(J10>0.01,"'ANOMALIE","'OK") -> 'OK
B12: Total | C12: =SUM(C9:C11) -> 15380.56 | D12: =SUM(D9:D11) -> 11465750 | H12: =SUM(H9:H11) -> 11465750 | I12: =SUM(I9:I11) -> 0.014809919 | J12: =+I12/C12/100 -> 9.6289858e-09 | K12: =IF(J12>0.01,"'ANOMALIE","'OK") -> 'OK

Sheet O.D Rééval
A1: Date | B1: journal | C1: Compte | D1: N° Piéces | E1: Libellé | F1: Debit | G1: Credit | H1: Monnaie
A2: =Sommaire!$C$1 -> 46022 | B2: OD-SITU | C2: 31800000 | E2: ="Valorisation au "&TEXT(Sommaire!$C$1,"jj/mm/aa") -> Valorisation au 31/12/25 | F2: =IF(SUMIF(Inventaire!B13:B90,"??OC*",Inventaire!M13:M90)>0,SUMIF(Inventaire!B13:B90,"??OC*",Inventaire!M13:M90),0) -> 0 | G2: =IF(SUMIF(Inventaire!B13:B90,"??OC*",Inventaire!M13:M90)<0,-SUMIF(Inventaire!B13:B90,"??OC*",Inventaire!M13:M90),0) -> 0 | H2: E | I2: Intérêts Courus sur OC
A3: =Sommaire!$C$1 -> 46022 | B3: OD-SITU | C3: 70110000 | E3: ="Valorisation au "&TEXT(Sommaire!$C$1,"jj/mm/aa") -> Valorisation au 31/12/25 | G3: =IF(SUMIF(Inventaire!B13:B90,"??OC*",Inventaire!M13:M90)>0,SUMIF(Inventaire!B13:B90,"??OC*",Inventaire!M13:M90),0) -> 0 | H3: E | I3: Intérêts courus sur OC | J3: OC
A5: =Sommaire!$C$1 -> 46022 | B5: OD-SITU | C5: 31800000 | E5: ="Valorisation au "&TEXT(Sommaire!$C$1,"jj/mm/aa") -> Valorisation au 31/12/25 | F5: =IF(SUMIF(Inventaire!B13:B90,"??OS*",Inventaire!M13:M90)+SUMIF(Inventaire!B13:B90,"??OR*",Inventaire!M13:M90)+SUMIF(Inventaire!B13:B90,"??CN*",Inventaire!M13:M90)>0,SUMIF(Inventaire!B13:B90,"??OS*",Inventaire!M13:M90)+SUMIF(Inventaire!B13:B90,"??OR*",Inventaire!M13:M90)+SUMIF(Inventaire!B13:B90,"??CN*",Inventaire!M13:M90),0) -> 0 | G5: =IF(SUMIF(Inventaire!B13:B90,"??OS*",Inventaire!M13:M90)+SUMIF(Inventaire!B13:B90,"??OR*",Inventaire!M13:M90)+SUMIF(Inventaire!B13:B90,"??CN*",Inventaire!M13:M90)<0,-(SUMIF(Inventaire!B13:B90,"??OS*",Inventaire!M13:M90)+SUMIF(Inventaire!B13:B90,"??OR*",Inventaire!M13:M90)+SUMIF(Inventaire!B13:B90,"??CN*",Inventaire!M13:M90)),0) -> 0 | H5: E | I5: Intérêts courus sur autres obligations
A6: =Sommaire!$C$1 -> 46022 | B6: OD-SITU | C6: 70000000 | E6: ="Valorisation au "&TEXT(Sommaire!$C$1,"jj/mm/aa") -> Valorisation au 31/12/25 | G6: =IF(SUMIF(Inventaire!B13:B90,"??OS*",Inventaire!M13:M90)+SUMIF(Inventaire!B13:B90,"??OR*",Inventaire!M13:M90)+SUMIF(Inventaire!B13:B90,"??CN*",Inventaire!M13:M90)>0,SUMIF(Inventaire!B13:B90,"??OS*",Inventaire!M13:M90)+SUMIF(Inventaire!B13:B90,"??OR*",Inventaire!M13:M90)+SUMIF(Inventaire!B13:B90,"??CN*",Inventaire!M13:M90),0) -> 0 | H6: E | I6: Intérêts courus sur autres obligations | J6: OS/OR/CN
A8: =Sommaire!$C$1 -> 46022 | B8: OD-SITU | C8: 36800000 | E8: ="Valorisation au "&TEXT(Sommaire!$C$1,"jj/mm/aa") -> Valorisation au 31/12/25 | F8: =IF(SUMIF(Inventaire!B13:B90,"??PR*",Inventaire!M13:M90)+SUMIF(Inventaire!B13:B90,"??NO*",Inventaire!M13:M90)+SUMIF(Inventaire!B13:B90,"??CC*",Inventaire!M13:M90)>0,SUMIF(Inventaire!B13:B90,"??PR*",Inventaire!M13:M90)+SUMIF(Inventaire!B13:B90,"??NO*",Inventaire!M13:M90)+SUMIF(Inventaire!B13:B90,"??CC*",Inventaire!M13:M90),0) -> 0 | G8: =IF(SUMIF(Inventaire!B13:B90,"??PR*",Inventaire!M13:M90)+SUMIF(Inventaire!B13:B90,"??NO*",Inventaire!M13:M90)+SUMIF(Inventaire!B13:B90,"??CC*",Inventaire!M13:M90)<0,-SUMIF(Inventaire!B13:B90,"??PR*",Inventaire!M13:M90)+SUMIF(Inventaire!B13:B90,"??NO*",Inventaire!M13:M90)+SUMIF(Inventaire!B13:B90,"??CC*",Inventaire!M13:M90),0) -> 0 | H8: E | I8: intérêts courus sur Prêt
A9: =Sommaire!$C$1 -> 46022 | B9: OD-SITU | C9: 70600000 | E9: ="Valorisation au "&TEXT(Sommaire!$C$1,"jj/mm/aa") -> Valorisation au 31/12/25 | G9: =IF(SUMIF(Inventaire!B13:B90,"??PR*",Inventaire!M13:M90)+SUMIF(Inventaire!B13:B90,"??NO*",Inventaire!M13:M90)+SUMIF(Inventaire!B13:B90,"??CC*",Inventaire!M13:M90)>0,SUMIF(Inventaire!B13:B90,"??PR*",Inventaire!M13:M90)+SUMIF(Inventaire!B13:B90,"??NO*",Inventaire!M13:M90)+SUMIF(Inventaire!B13:B90,"??CC*",Inventaire!M13:M90),0) -> 0 | H9: E | I9: intérêts courus sur Prêt | J9: PR/CC/NO
A11: =Sommaire!$C$1 -> 46022 | B11: OD-SITU | C11: 36800000 | E11: ="Valorisation au "&TEXT(Sommaire!$C$1,"jj/mm/aa") -> Valorisation au 31/12/25 | F11: =IF(+SUMIF(Inventaire!B16:B93,"??CT*",Inventaire!M16:M93)>0,+SUMIF(Inventaire!B16:B93,"??CT*",Inventaire!M16:M93),0) -> 0 | G11: =IF(+SUMIF(Inventaire!B16:B93,"??CT*",Inventaire!M16:M93)<0,-SUMIF(Inventaire!B16:B93,"??CT*",Inventaire!M16:M93),0) -> 0 | H11: E | I11: intérêts courus sur dépôt
A12: =Sommaire!$C$1 -> 46022 | B12: OD-SITU | C12: 70600000 | E12: ="Valorisation au "&TEXT(Sommaire!$C$1,"jj/mm/aa") -> Valorisation au 31/12/25 | G12: =IF(+SUMIF(Inventaire!B16:B93,"??CT*",Inventaire!M16:M93)>0,+SUMIF(Inventaire!B16:B93,"??CT*",Inventaire!M16:M93),0) -> 0 | H12: E | I12: intérêts courus sur dépôt | J12: CT
A14: =Sommaire!$C$1 -> 46022 | B14: OD-SITU | C14: 36800000 | E14: ="Valorisation au "&TEXT(Sommaire!$C$1,"jj/mm/aa") -> Valorisation au 31/12/25 | F14: =IF(SUMIF(Inventaire!B13:B90,"??AC*",Inventaire!M13:M90)+SUMIF(Inventaire!B13:B90,"??AD*",Inventaire!M13:M90)+SUMIF(Inventaire!B13:B90,"??SA*",Inventaire!M13:M90)+SUMIF(Inventaire!B13:B90,"??BS*",Inventaire!M13:M90)>0,SUMIF(Inventaire!B13:B90,"??AC*",Inventaire!M13:M90)+SUMIF(Inventaire!B13:B90,"??AD*",Inventaire!M13:M90)+SUMIF(Inventaire!B13:B90,"??SA*",Inventaire!M13:M90)+SUMIF(Inventaire!B13:B90,"??BS*",Inventaire!M13:M90),0) -> 0 | G14: =IF(SUMIF(Inventaire!B13:B90,"??AC*",Inventaire!M13:M90)+SUMIF(Inventaire!B13:B90,"??AD*",Inventaire!M13:M90)+SUMIF(Inventaire!B13:B90,"??SA*",Inventaire!M13:M90)+SUMIF(Inventaire!B13:B90,"??BS*",Inventaire!M13:M90)<0,-SUMIF(Inventaire!B13:B90,"??AC*",Inventaire!M13:M90)+SUMIF(Inventaire!B13:B90,"??AD*",Inventaire!M13:M90)+SUMIF(Inventaire!B13:B90,"??SA*",Inventaire!M13:M90)+SUMIF(Inventaire!B13:B90,"??BS*",Inventaire!M13:M90),0) -> 0 | H14: E | I14: Intérêts courus sur actions
A15: =Sommaire!$C$1 -> 46022 | B15: OD-SITU | C15: 70000000 | E15: ="Valorisation au "&TEXT(Sommaire!$C$1,"jj/mm/aa") -> Valorisation au 31/12/25 | F15: =IF(SUMIF(Inventaire!B13:B90,"??AC*",Inventaire!M13:M90)+SUMIF(Inventaire!B13:B90,"??AD*",Inventaire!M13:M90)+SUMIF(Inventaire!B13:B90,"??SA*",Inventaire!M13:M90)+SUMIF(Inventaire!B13:B90,"??BS*",Inventaire!M13:M90)<0,-SUMIF(Inventaire!B13:B90,"??AC*",Inventaire!M13:M90)+SUMIF(Inventaire!B13:B90,"??AD*",Inventaire!M13:M90)+SUMIF(Inventaire!B13:B90,"??SA*",Inventaire!M13:M90)+SUMIF(Inventaire!B13:B90,"??BS*",Inventaire!M13:M90),0) -> 0 | G15: =IF(SUMIF(Inventaire!B13:B90,"??AC*",Inventaire!M13:M90)+SUMIF(Inventaire!B13:B90,"??AD*",Inventaire!M13:M90)+SUMIF(Inventaire!B13:B90,"??SA*",Inventaire!M13:M90)+SUMIF(Inventaire!B13:B90,"??BS*",Inventaire!M13:M90)>0,SUMIF(Inventaire!B13:B90,"??AC*",Inventaire!M13:M90)+SUMIF(Inventaire!B13:B90,"??AD*",Inventaire!M13:M90)+SUMIF(Inventaire!B13:B90,"??SA*",Inventaire!M13:M90)+SUMIF(Inventaire!B13:B90,"??BS*",Inventaire!M13:M90),0) -> 0 | H15: E | I15: Intérêts courus sur actions | J15: AC/AD/BS/SA
A17: =Sommaire!$C$1 -> 46022 | B17: OD-SITU | C17: 37000000 | E17: ="Valorisation au "&TEXT(Sommaire!$C$1,"jj/mm/aa") -> Valorisation au 31/12/25 | F17: =IF(SUMIF(Inventaire!B13:B90,"??AC*",Inventaire!L13:L90)+SUMIF(Inventaire!B13:B90,"??AD*",Inventaire!L13:L90)+SUMIF(Inventaire!B13:B90,"??SA*",Inventaire!L13:L90)+SUMIF(Inventaire!B13:B90,"??BS*",Inventaire!L13:L90)>0,(SUMIF(Inventaire!B13:B90,"??AC*",Inventaire!L13:L90)+SUMIF(Inventaire!B13:B90,"??AD*",Inventaire!L13:L90)+SUMIF(Inventaire!B13:B90,"??SA*",Inventaire!L13:L90)+SUMIF(Inventaire!B13:B90,"??BS*",Inventaire!L13:L90)),0) -> 0 | G17: =IF(SUMIF(Inventaire!B13:B90,"??AC*",Inventaire!L13:L90)+SUMIF(Inventaire!B13:B90,"??AD*",Inventaire!L13:L90)+SUMIF(Inventaire!B13:B90,"??SA*",Inventaire!L13:L90)+SUMIF(Inventaire!B13:B90,"??BS*",Inventaire!L13:L90)<0,-(SUMIF(Inventaire!B13:B90,"??AC*",Inventaire!L13:L90)+SUMIF(Inventaire!B13:B90,"??AD*",Inventaire!L13:L90)+SUMIF(Inventaire!B13:B90,"??SA*",Inventaire!L13:L90)+SUMIF(Inventaire!B13:B90,"??BS*",Inventaire!L13:L90)),0) -> 3633212.3 | H17: E | I17: PVMV latentes nettes s/actions
A18: =Sommaire!$C$1 -> 46022 | B18: OD-SITU | C18: 75500000 | E18: ="Valorisation au "&TEXT(Sommaire!$C$1,"jj/mm/aa") -> Valorisation au 31/12/25 | F18: =IF(SUMIF(Inventaire!B13:B90,"??AC*",Inventaire!L13:L90)+SUMIF(Inventaire!B13:B90,"??AD*",Inventaire!L13:L90)+SUMIF(Inventaire!B13:B90,"??SA*",Inventaire!L13:L90)+SUMIF(Inventaire!B13:B90,"??BS*",Inventaire!L13:L90)<0,-(SUMIF(Inventaire!B13:B90,"??AC*",Inventaire!L13:L90)+SUMIF(Inventaire!B13:B90,"??AD*",Inventaire!L13:L90)+SUMIF(Inventaire!B13:B90,"??SA*",Inventaire!L13:L90)+SUMIF(Inventaire!B13:B90,"??BS*",Inventaire!L13:L90)),0) -> 3633212.3 | G18: =IF(SUMIF(Inventaire!B13:B90,"??AC*",Inventaire!L13:L90)+SUMIF(Inventaire!B13:B90,"??AD*",Inventaire!L13:L90)+SUMIF(Inventaire!B13:B90,"??SA*",Inventaire!L13:L90)+SUMIF(Inventaire!B13:B90,"??BS*",Inventaire!L13:L90)>0,(SUMIF(Inventaire!B13:B90,"??AC*",Inventaire!L13:L90)+SUMIF(Inventaire!B13:B90,"??AD*",Inventaire!L13:L90)+SUMIF(Inventaire!B13:B90,"??SA*",Inventaire!L13:L90)+SUMIF(Inventaire!B13:B90,"??BS*",Inventaire!L13:L90)),0) -> 0 | H18: E | I18: PVMV latentes nettes s/actions
A20: =Sommaire!$C$1 -> 46022 | B20: OD-SITU | C20: 37100000 | E20: ="Valorisation au "&TEXT(Sommaire!$C$1,"jj/mm/aa") -> Valorisation au 31/12/25 | F20: =IF(SUMIF(Inventaire!B13:B90,"??OC*",Inventaire!L13:L90)>0,(SUMIF(Inventaire!B13:B90,"??OC*",Inventaire!L13:L90)),0) -> 0 | G20: =IF(SUMIF(Inventaire!B13:B90,"??OC*",Inventaire!L13:L90)<0,-(SUMIF(Inventaire!B13:B90,"??OC*",Inventaire!L13:L90)),0) -> 0 | H20: E | I20: PVMV latentes nettes s/obligations convertibles en actions
A21: =Sommaire!$C$1 -> 46022 | B21: OD-SITU | C21: 75512000 | E21: ="Valorisation au "&TEXT(Sommaire!$C$1,"jj/mm/aa") -> Valorisation au 31/12/25 | F21: =IF(SUMIF(Inventaire!B13:B90,"??OC*",Inventaire!L13:L90)<0,-(SUMIF(Inventaire!B13:B90,"??OC*",Inventaire!L13:L90)),0) -> 0 | G21: =IF(SUMIF(Inventaire!B13:B90,"??OC*",Inventaire!L13:L90)>0,(SUMIF(Inventaire!B13:B90,"??OC*",Inventaire!L13:L90)),0) -> 0 | H21: E | I21: PVMV latentes nettes s/obligations convertibles en actions
A23: =Sommaire!$C$1 -> 46022 | B23: OD-SITU | C23: 37100000 | E23: ="Valorisation au "&TEXT(Sommaire!$C$1,"jj/mm/aa") -> Valorisation au 31/12/25 | F23: =IF(SUMIF(Inventaire!B13:B90,"??OS*",Inventaire!L13:L90)+SUMIF(Inventaire!B13:B90,"??OR*",Inventaire!L13:L90)+SUMIF(Inventaire!B13:B90,"??CN*",Inventaire!L13:L90)>0,+(SUMIF(Inventaire!B13:B90,"??OS*",Inventaire!L13:L90)+SUMIF(Inventaire!B13:B90,"??OR*",Inventaire!L13:L90)+SUMIF(Inventaire!B13:B90,"??CN*",Inventaire!L13:L90)),0) -> 0 | G23: =IF(SUMIF(Inventaire!B13:B90,"??OS*",Inventaire!L13:L90)+SUMIF(Inventaire!B13:B90,"??OR*",Inventaire!L13:L90)+SUMIF(Inventaire!B13:B90,"??CN*",Inventaire!L13:L90)<0,-(SUMIF(Inventaire!B13:B90,"??OS*",Inventaire!L13:L90)+SUMIF(Inventaire!B13:B90,"??OR*",Inventaire!L13:L90)+SUMIF(Inventaire!B13:B90,"??CN*",Inventaire!L13:L90)),0) -> 0 | H23: E | I23: PVMV latentes nettes s/autres obligations
A24: =Sommaire!$C$1 -> 46022 | B24: OD-SITU | C24: 75515000 | E24: ="Valorisation au "&TEXT(Sommaire!$C$1,"jj/mm/aa") -> Valorisation au 31/12/25 | F24: =IF(SUMIF(Inventaire!B13:B90,"??OS*",Inventaire!L13:L90)+SUMIF(Inventaire!B13:B90,"??OR*",Inventaire!L13:L90)+SUMIF(Inventaire!B13:B90,"??CN*",Inventaire!L13:L90)<0,-(SUMIF(Inventaire!B13:B90,"??OS*",Inventaire!L13:L90)+SUMIF(Inventaire!B13:B90,"??OR*",Inventaire!L13:L90)+SUMIF(Inventaire!B13:B90,"??CN*",Inventaire!L13:L90)),0) -> 0 | G24: =IF(SUMIF(Inventaire!B13:B90,"??OS*",Inventaire!L13:L90)+SUMIF(Inventaire!B13:B90,"??OR*",Inventaire!L13:L90)+SUMIF(Inventaire!B13:B90,"??CN*",Inventaire!L13:L90)>0,+(SUMIF(Inventaire!B13:B90,"??OS*",Inventaire!L13:L90)+SUMIF(Inventaire!B13:B90,"??OR*",Inventaire!L13:L90)+SUMIF(Inventaire!B13:B90,"??CN*",Inventaire!L13:L90)),0) -> 0 | H24: E | I24: PVMV latentes nettes s/autres obligations
A26: =Sommaire!$C$1 -> 46022 | B26: OD-SITU | C26: 37600000 | E26: ="Valorisation au "&TEXT(Sommaire!$C$1,"jj/mm/aa") -> Valorisation au 31/12/25 | F26: =IF(SUMIF(Inventaire!B13:B90,"??PR*",Inventaire!L13:L90)+SUMIF(Inventaire!B13:B90,"??NO*",Inventaire!L13:L90)+SUMIF(Inventaire!B13:B90,"??CC*",Inventaire!L13:L90)+SUMIF(Inventaire!B13:B90,"??CT*",Inventaire!L13:L90)>0,+(SUMIF(Inventaire!B13:B90,"??PR*",Inventaire!L13:L90)+SUMIF(Inventaire!B13:B90,"??NO*",Inventaire!L13:L90)+SUMIF(Inventaire!B13:B90,"??CT*",Inventaire!L13:L90)+SUMIF(Inventaire!B13:B90,"??CC*",Inventaire!L13:L90)),0) -> 0 | G26: =IF(SUMIF(Inventaire!B13:B90,"??PR*",Inventaire!L13:L90)+SUMIF(Inventaire!B13:B90,"??NO*",Inventaire!L13:L90)+SUMIF(Inventaire!B13:B90,"??CC*",Inventaire!L13:L90)+SUMIF(Inventaire!B13:B90,"??CT*",Inventaire!L13:L90)<0,-(SUMIF(Inventaire!B13:B90,"??PR*",Inventaire!L13:L90)+SUMIF(Inventaire!B13:B90,"??NO*",Inventaire!L13:L90)+SUMIF(Inventaire!B13:B90,"??CT*",Inventaire!L13:L90)+SUMIF(Inventaire!B13:B90,"??CC*",Inventaire!L13:L90)),0) -> 0 | H26: E | I26: PVMV latentes nettes s/dépôt et autres investissements financiers
A27: =Sommaire!$C$1 -> 46022 | B27: OD-SITU | C27: 75561000 | E27: ="Valorisation au "&TEXT(Sommaire!$C$1,"jj/mm/aa") -> Valorisation au 31/12/25 | F27: =IF(SUMIF(Inventaire!B13:B90,"??PR*",Inventaire!L13:L90)+SUMIF(Inventaire!B13:B90,"??NO*",Inventaire!L13:L90)+SUMIF(Inventaire!B13:B90,"??CC*",Inventaire!L13:L90)+SUMIF(Inventaire!B13:B90,"??CT*",Inventaire!L13:L90)<0,-(SUMIF(Inventaire!B13:B90,"??PR*",Inventaire!L13:L90)+SUMIF(Inventaire!B13:B90,"??NO*",Inventaire!L13:L90)+SUMIF(Inventaire!B13:B90,"??CT*",Inventaire!L13:L90)+SUMIF(Inventaire!B13:B90,"??CC*",Inventaire!L13:L90)),0) -> 0 | G27: =IF(SUMIF(Inventaire!B13:B90,"??PR*",Inventaire!L13:L90)+SUMIF(Inventaire!B13:B90,"??NO*",Inventaire!L13:L90)+SUMIF(Inventaire!B13:B90,"??CC*",Inventaire!L13:L90)+SUMIF(Inventaire!B13:B90,"??CT*",Inventaire!L13:L90)>0,+(SUMIF(Inventaire!B13:B90,"??PR*",Inventaire!L13:L90)+SUMIF(Inventaire!B13:B90,"??NO*",Inventaire!L13:L90)+SUMIF(Inventaire!B13:B90,"??CT*",Inventaire!L13:L90)+SUMIF(Inventaire!B13:B90,"??CC*",Inventaire!L13:L90)),0) -> 0 | H27: E | I27: PVMV latentes nettes s/dépôt et autres investissements financiers
A29: =Sommaire!$C$1 -> 46022 | B29: OD-SITU | C29: 37300000 | E29: ="Valorisation au "&TEXT(Sommaire!$C$1,"jj/mm/aa") -> Valorisation au 31/12/25 | F29: =IF(SUMIF(Inventaire!C13:C90,"*sicav*",Inventaire!L13:L90)+SUMIF(Inventaire!C13:C90,"*FCP*",Inventaire!L13:L90)+SUMIF(Inventaire!C13:C90,"*FPCI*",Inventaire!L13:L90)+SUMIF(Inventaire!C13:C90,"*SLP*",Inventaire!L13:L90)+SUMIF(Inventaire!C13:C90,"*FIPS*",Inventaire!L13:L90)>0,(SUMIF(Inventaire!C13:C90,"*sicav*",Inventaire!L13:L90)+SUMIF(Inventaire!C13:C90,"*FCP*",Inventaire!L13:L90)+SUMIF(Inventaire!C13:C90,"*FPCI*",Inventaire!L13:L90)+SUMIF(Inventaire!C13:C90,"*SLP*",Inventaire!L13:L90)+SUMIF(Inventaire!C13:C90,"*FIPS*",Inventaire!L13:L90)),0) -> 0 | G29: =IF(SUMIF(Inventaire!C13:C90,"*sicav*",Inventaire!L13:L90)+SUMIF(Inventaire!C13:C90,"*FCP*",Inventaire!L13:L90)+SUMIF(Inventaire!C13:C90,"*FPCI*",Inventaire!L13:L90)+SUMIF(Inventaire!C13:C90,"*SLP*",Inventaire!L13:L90)+SUMIF(Inventaire!C13:C90,"*FIPS*",Inventaire!L13:L90)<0,-(SUMIF(Inventaire!C13:C90,"*sicav*",Inventaire!L13:L90)+SUMIF(Inventaire!C13:C90,"*FCP*",Inventaire!L13:L90)+SUMIF(Inventaire!C13:C90,"*FPCI*",Inventaire!L13:L90)+SUMIF(Inventaire!C13:C90,"*SLP*",Inventaire!L13:L90)+SUMIF(Inventaire!C13:C90,"*FIPS*",Inventaire!L13:L90)),0) -> 0 | H29: E | I29: PVMV latentes nettes s/OPC
A30: =Sommaire!$C$1 -> 46022 | B30: OD-SITU | C30: 75530000 | E30: ="Valorisation au "&TEXT(Sommaire!$C$1,"jj/mm/aa") -> Valorisation au 31/12/25 | F30: =IF(SUMIF(Inventaire!C13:C90,"*sicav*",Inventaire!L13:L90)+SUMIF(Inventaire!C13:C90,"*FCP*",Inventaire!L13:L90)+SUMIF(Inventaire!C13:C90,"*FPCI*",Inventaire!L13:L90)+SUMIF(Inventaire!C13:C90,"*SLP*",Inventaire!L13:L90)+SUMIF(Inventaire!C13:C90,"*FIPS*",Inventaire!L13:L90)<0,-(SUMIF(Inventaire!C13:C90,"*sicav*",Inventaire!L13:L90)+SUMIF(Inventaire!C13:C90,"*FCP*",Inventaire!L13:L90)+SUMIF(Inventaire!C13:C90,"*FPCI*",Inventaire!L13:L90)+SUMIF(Inventaire!C13:C90,"*SLP*",Inventaire!L13:L90)+SUMIF(Inventaire!C13:C90,"*FIPS*",Inventaire!L13:L90)),0) -> 0 | G30: =IF(SUMIF(Inventaire!C13:C90,"*sicav*",Inventaire!L13:L90)+SUMIF(Inventaire!C13:C90,"*FCP*",Inventaire!L13:L90)+SUMIF(Inventaire!C13:C90,"*FPCI*",Inventaire!L13:L90)+SUMIF(Inventaire!C13:C90,"*SLP*",Inventaire!L13:L90)+SUMIF(Inventaire!C13:C90,"*FIPS*",Inventaire!L13:L90)>0,(SUMIF(Inventaire!C13:C90,"*sicav*",Inventaire!L13:L90)+SUMIF(Inventaire!C13:C90,"*FCP*",Inventaire!L13:L90)+SUMIF(Inventaire!C13:C90,"*FPCI*",Inventaire!L13:L90)+SUMIF(Inventaire!C13:C90,"*SLP*",Inventaire!L13:L90)+SUMIF(Inventaire!C13:C90,"*FIPS*",Inventaire!L13:L90)),0) -> 0 | H30: E | I30: PVMV latentes nettes s/OPC | J30: Sicav/FCP/FPCI/SLP/FIPS
A33: =Sommaire!$C$1 -> 46022 | B33: OD-SITU | C33: 10410000 | E33: ="Valorisation au "&TEXT(Sommaire!$C$1,"jj/mm/aa") -> Valorisation au 31/12/25 | G33: 0 | H33: E | I33: Fund reserve
A34: =Sommaire!$C$1 -> 46022 | B34: OD-SITU | C34: 48700000 | E34: ="Valorisation au "&TEXT(Sommaire!$C$1,"jj/mm/aa") -> Valorisation au 31/12/25 | F34: 0 | G34: =F33 -> 0 | H34: E | I34: =+I33 -> Fund reserve
A36: =Sommaire!$C$1 -> 46022 | B36: OD-SITU | C36: 39800000 | E36: ="Valorisation au "&TEXT(Sommaire!$C$1,"jj/mm/aa") -> Valorisation au 31/12/25 | F36: 0 | G36: =Emprunt!K68 -> 0 | H36: E | I36: Intérêts sur emprunts
A37: =Sommaire!$C$1 -> 46022 | B37: OD-SITU | C37: 60500000 | E37: ="Valorisation au "&TEXT(Sommaire!$C$1,"jj/mm/aa") -> Valorisation au 31/12/25 | F37: =G36 -> 0 | G37: =F36 -> 0 | H37: E | I37: Intérêts sur emprunts
E41: Contrôle | F41: =SUM(F2:F40) -> 3633212.3 | G41: =SUM(G3:G40) -> 3633212.3
E42: écart | G42: =F41-G41 -> 0 | H42: ce contrôle toujours à zéro
G43: =IF(G42=0,"OK","ANOMALIE") -> OK
A47: à la clôture
A48: =A2 -> 46022 | B48: OD | C48: =C2 -> 31800000 | E48: =E2 -> Valorisation au 31/12/25 | F48: =F2 -> 0 | G48: =G2 -> 0 | H48: =H2 -> E | I48: =I2 -> Intérêts Courus sur OC
A49: =A3 -> 46022 | B49: OD | C49: =C3 -> 70110000 | E49: =E3 -> Valorisation au 31/12/25 | F49: =F3 -> 0 | G49: =G3 -> 0 | H49: =H3 -> E | I49: =I3 -> Intérêts courus sur OC
A51: =A5 -> 46022 | B51: OD | C51: =C5 -> 31800000 | E51: =E5 -> Valorisation au 31/12/25 | F51: =F5 -> 0 | G51: =G5 -> 0 | H51: =H5 -> E | I51: =I5 -> Intérêts courus sur autres obligations
A52: =A6 -> 46022 | B52: OD | C52: =C6 -> 70000000 | E52: =E6 -> Valorisation au 31/12/25 | F52: =F6 -> 0 | G52: =G6 -> 0 | H52: =H6 -> E | I52: =I6 -> Intérêts courus sur autres obligations
A54: =A8 -> 46022 | B54: OD | C54: =C8 -> 36800000 | E54: =E8 -> Valorisation au 31/12/25 | F54: =F8 -> 0 | G54: =G8 -> 0 | H54: =H8 -> E | I54: =I8 -> intérêts courus sur Prêt
A55: =A9 -> 46022 | B55: OD | C55: =C9 -> 70600000 | E55: =E9 -> Valorisation au 31/12/25 | F55: =F9 -> 0 | G55: =G9 -> 0 | H55: =H9 -> E | I55: =I9 -> intérêts courus sur Prêt
A57: =A14 -> 46022 | B57: OD | C57: =C14 -> 36800000 | E57: =E14 -> Valorisation au 31/12/25 | F57: =F14 -> 0 | G57: =G14 -> 0 | H57: =H14 -> E | I57: =I14 -> Intérêts courus sur actions
A58: =A15 -> 46022 | B58: OD | C58: =C15 -> 70000000 | E58: =E15 -> Valorisation au 31/12/25 | F58: =F15 -> 0 | G58: =G15 -> 0 | H58: =H15 -> E | I58: =I15 -> Intérêts courus sur actions
A60: =A17 -> 46022 | B60: OD | C60: =C17 -> 37000000 | E60: =E17 -> Valorisation au 31/12/25 | F60: =F17 -> 0 | G60: =G17 -> 3633212.3 | H60: =H17 -> E | I60: =I17 -> PVMV latentes nettes s/actions
A61: =A18 -> 46022 | B61: OD | C61: =C18 -> 75500000 | E61: =E18 -> Valorisation au 31/12/25 | F61: =F18 -> 3633212.3 | G61: =G18 -> 0 | H61: =H18 -> E | I61: =I18 -> PVMV latentes nettes s/actions
A63: =A20 -> 46022 | B63: OD | C63: =C20 -> 37100000 | E63: =E20 -> Valorisation au 31/12/25 | F63: =F20 -> 0 | G63: =G20 -> 0 | H63: =H20 -> E | I63: =I20 -> PVMV latentes nettes s/obligations convertibles en actions
...

Sheet Rappro Titres & Parts
B1: =Inventaire!B1 -> SANCY - SLP | E1: Rapprochement Titres | J1: =Sommaire!C1 -> 46022
B4: Société et nature juridique | C4: Quantité | D4: Quantité | E4: Date | F4: Ecart | G4: Quantité | H4: Date relevé dépositaire | I4: Ecart | J4: Commentaires
B5: de l'instrument financier | C5: inventaire | D5: société | E5: attestation | F5: émetteur | G5: dépositaire | I5: dépositaire
B7: =Inventaire!C16 -> Heka Invest - Actions | C7: =Inventaire!D16 -> 14423076 | D7: 14423076 | E7: 45657 | F7: =C7-D7 -> 0 | G7: 14423076 | H7: 46022 | I7: =C7-G7 -> 0
F8: =C8-D8 -> 0 | I8: =C8-G8 -> 0
F9: =C9-D9 -> 0 | I9: =C9-G9 -> 0
F10: =C10-D10 -> 0 | I10: =C10-G10 -> 0
F11: =C11-D11 -> 0 | I11: =C11-G11 -> 0
C12: =SUM(C6:C11) -> 14423076 | D12: =SUM(D6:D11) -> 14423076 | F12: =SUM(F6:F11) -> 0 | G12: =SUM(G6:G11) -> 14423076 | I12: =SUM(I6:I11) -> 0
F13: =IF(ABS(F12)<0.01,"","Anomalie AIC") | I13: =IF(ABS(I12)<0.01,"","Anomalie dépositaire")
F15: Contrôle formule
E16: Contrôle | F16: =C12-D12 -> 0 | H16: Contrôle | I16: =C12-G12 -> 0
B17: Contrôle avec l'inventaire | C17: Nombre de lignes | E17: Ecart | F17: =F12-F16 -> 0 | H17: Ecart | I17: =I12-I16 -> 0
B18: Rapprochement titres | C18: =COUNT(C7:C11) -> 1 | F18: =IF(ABS(F17)>0.01,"ANOMALIE","OK") -> OK | I18: =IF(ABS(I17)>0.01,"ANOMALIE","OK") -> OK
B19: inventaire | C19: =COUNT(Inventaire!G15:G22) -> 1
C20: =IF(C18-C19<>0,"Rapprochement titres incomplet","OK") -> OK | E20: Rapprochement Parts
B23: Parts émises par | C23: Quantité | D23: Quantité | E23: Date | F23: ECART | G23: Commentaires
B24: le fonds | C24: Fonds | D24: Dépositaire | E24: attestation
B26: =+'Calcul VL'!B9 -> Parts A | C26: =+'Calcul VL'!C9 -> 15379.56 | D26: 15379.56 | E26: 46022 | F26: =C26-D26 -> 0
B27: =+'Calcul VL'!B10 -> Part de commandité | C27: =+'Calcul VL'!C10 -> 1 | D27: 1 | E27: 46022 | F27: =C27-D27 -> 0
C29: =SUM(C26:C28) -> 15380.56 | D29: =SUM(D26:D28) -> 15380.56 | F29: =SUM(F26:F28) -> 0

Sheet Hors bilan
B1: ='Calcul VL'!B1 -> SANCY - SLP | C1: HORS BILAN au | D1: =Sommaire!C1 -> 46022
D5: Exercice | E5: Exercice N-1 | F5: Exercice | G5: Exercice | H5: Exercice | I5: Exercice | J5: Exercice
B6: Autres engagements (par nature de produit) | D6: =+D1 -> 46022 | E6: 45657 | F6: 39447 | G6: 39082 | H6: 38717 | I6: 38352 | J6: 37986
B8: Garanties reçues | D8: =E34 -> 0 | E8: 0
B9: dont instruments financiers reçus en garantie et non inscrits au bilan
B11: Garanties données | D11: =D34 -> 0 | E11: 0
B12: dont instruments financiers donnés en garantie et maintenus dans leur poste d'origine
B14: Engagements de financement reçu mais non encore tirés | D14: =E38 -> 0 | E14: 0
B16: Engagements de financement donnés mais non encore tirés | D16: =D38 -> 0 | E16: 0
B18: Autres engagements hors bilan
C19: Donnés | D19: =D42 -> 0 | E19: 0
C20: reçus | D20: =E42 -> 0 | E20: 179291.18
B25: =+B1 -> SANCY - SLP | C25: DETAIL DES ENGAGEMENTS HORS-BILAN au | E25: =+D1 -> 46022
D28: Engagements hors bilan
D29: Engagements donnés | E29: Engagements reçus | F29: Commentaires
B30: Garanties
B34: Sous-total | D34: =SUM(D30:D33) -> 0 | E34: =SUM(E30:E33) -> 0
B35: Engagements de financement mais non encore tirés
B38: Sous-total | D38: =SUM(D35:D37) -> 0 | E38: =SUM(E35:E37) -> 0
B39: Autres engagements hors bilan | E39: ,
B42: Sous-total | D42: =SUM(D39:D41) -> 0 | E42: =SUM(E39:E41) -> 0

Sheet PVMV
B1: ='Rappro Titres & Parts'!B1 -> SANCY - SLP | G1: SUIVI DES ACHATS VENTES SUR TITRES : | K1: =Sommaire!C1 -> 46022 | Q1: AIFM Turn over | R1: =SUMIFS(J:J,D:D,">" & T1,D:D,"<=" & K1,C:C,"<>Récap")+SUMIFS(G:G,D:D,">" & T1,D:D,"<=" & K1,C:C,"<>Récap")-R2 -> 0 | T1: =DATE(YEAR(K1)+U1,MONTH(K1),DAY(K1)) -> 45657 | U1: -1
Q2: Collective Investment Undertakings | R2: =SUMIFS(J:J,D:D,">" & T1,D:D,"<=" & K1,C:C,"<>Récap",A:A,"x")+SUMIFS(G:G,D:D,">" & T1,D:D,"<=" & K1,C:C,"<>Récap",A:A,"x") -> 0
B3: Les instruments financiers sont comptabilisés "frais inclus". | E3: ACHATS | H3: VENTES | L3: SOLDES | O3: PLUS VALUES REALISEES | P3: MOINS VALUES REALISEES | Q3: Prix de vente- prix de revient (1) | R3: Sommes des plus ou moins values (2) | S3: Contrôle (1)-(2)
C4: LIBELLE | D4: DATE OPE | E4: QTE | F4: PR UNITAIRE | G4: PR OPERATION | H4: QTE | I4: PV UNITAIRE | J4: PV OPERATION | K4: PR OPERATION | L4: QUANTITE | M4: PR CUMULE | N4: PR UNIT. MOYEN | Q4: Plus ou moins values nettes | R4: Plus ou moins values nettes | S4: Contrôle
C5: Report | N5: =+IF(L5=0,0,M5/L5) -> 0 | O5: =IF(J5-K5>0,J5-K5,0) -> 0 | P5: =IF(J5-K5<0,J5-K5,0) -> 0 | Q5: =+J5-K5 -> 0 | R5: =+O5+P5 -> 0 | S5: =+Q5-R5 -> 0
B6: Heka Invest - Actions | C6: Reprise | D6: 45107 | E6: 14423076 | F6: =IF(E6=0,0,G6/E6) -> 1.04 | G6: 14999999 | I6: =IF(H6=0,0,J6/H6) -> 0 | K6: =+H6*N5 -> 0 | L6: =+L5+E6-H6 -> 14423076 | M6: =+M5+G6-K6 -> 14999999 | N6: =+IF(L6=0,0,M6/L6) -> 1.04 | O6: =IF(J6-K6>0,J6-K6,0) -> 0 | P6: =IF(J6-K6<0,J6-K6,0) -> 0 | Q6: =+J6-K6 -> 0 | R6: =+O6+P6 -> 0 | S6: =+Q6-R6 -> 0
B7: =B6 -> Heka Invest - Actions | F7: =IF(E7=0,0,G7/E7) -> 0 | I7: =IF(H7=0,0,J7/H7) -> 0 | K7: =+H7*N6 -> 0 | L7: =+L6+E7-H7 -> 14423076 | M7: =+M6+G7-K7 -> 14999999 | N7: =+IF(L7=0,0,M7/L7) -> 1.04 | O7: =IF(J7-K7>0,J7-K7,0) -> 0 | P7: =IF(J7-K7<0,J7-K7,0) -> 0 | Q7: =+J7-K7 -> 0 | R7: =+O7+P7 -> 0 | S7: =+Q7-R7 -> 0
B8: =B7 -> Heka Invest - Actions | F8: =IF(E8=0,0,G8/E8) -> 0 | I8: =IF(H8=0,0,J8/H8) -> 0 | K8: =+H8*N7 -> 0 | L8: =+L7+E8-H8 -> 14423076 | M8: =+M7+G8-K8 -> 14999999 | N8: =+IF(L8=0,0,M8/L8) -> 1.04 | O8: =IF(J8-K8>0,J8-K8,0) -> 0 | P8: =IF(J8-K8<0,J8-K8,0) -> 0 | Q8: =+J8-K8 -> 0 | R8: =+O8+P8 -> 0 | S8: =+Q8-R8 -> 0
B9: =B8 -> Heka Invest - Actions | F9: =IF(E9=0,0,G9/E9) -> 0 | I9: =IF(H9=0,0,J9/H9) -> 0 | K9: =+H9*N8 -> 0 | L9: =+L8+E9-H9 -> 14423076 | M9: =+M8+G9-K9 -> 14999999 | N9: =+IF(L9=0,0,M9/L9) -> 1.04 | O9: =IF(J9-K9>0,J9-K9,0) -> 0 | P9: =IF(J9-K9<0,J9-K9,0) -> 0 | Q9: =+J9-K9 -> 0 | R9: =+O9+P9 -> 0 | S9: =+Q9-R9 -> 0
B10: =B9 -> Heka Invest - Actions | F10: =IF(E10=0,0,G10/E10) -> 0 | I10: =IF(H10=0,0,J10/H10) -> 0 | K10: =+H10*N9 -> 0 | L10: =+L9+E10-H10 -> 14423076 | M10: =+M9+G10-K10 -> 14999999 | N10: =+IF(L10=0,0,M10/L10) -> 1.04 | O10: =IF(J10-K10>0,J10-K10,0) -> 0 | P10: =IF(J10-K10<0,J10-K10,0) -> 0 | Q10: =+J10-K10 -> 0 | R10: =+O10+P10 -> 0 | S10: =+Q10-R10 -> 0
B11: =B10 -> Heka Invest - Actions | F11: =IF(E11=0,0,G11/E11) -> 0 | I11: =IF(H11=0,0,J11/H11) -> 0 | K11: =+H11*N10 -> 0 | L11: =+L10+E11-H11 -> 14423076 | M11: =+M10+G11-K11 -> 14999999 | N11: =+IF(L11=0,0,M11/L11) -> 1.04 | O11: =IF(J11-K11>0,J11-K11,0) -> 0 | P11: =IF(J11-K11<0,J11-K11,0) -> 0 | Q11: =+J11-K11 -> 0 | R11: =+O11+P11 -> 0 | S11: =+Q11-R11 -> 0
B12: =B11 -> Heka Invest - Actions | F12: =IF(E12=0,0,G12/E12) -> 0 | I12: =IF(H12=0,0,J12/H12) -> 0 | K12: =+H12*N11 -> 0 | L12: =+L11+E12-H12 -> 14423076 | M12: =+M11+G12-K12 -> 14999999 | N12: =+IF(L12=0,0,M12/L12) -> 1.04 | O12: =IF(J12-K12>0,J12-K12,0) -> 0 | P12: =IF(J12-K12<0,J12-K12,0) -> 0 | Q12: =+J12-K12 -> 0 | R12: =+O12+P12 -> 0 | S12: =+Q12-R12 -> 0
B13: =B12 -> Heka Invest - Actions | F13: =IF(E13=0,0,G13/E13) -> 0 | I13: =IF(H13=0,0,J13/H13) -> 0 | K13: =+H13*N7 -> 0 | L13: =+L12+E13-H13 -> 14423076 | M13: =+M12+G13-K13 -> 14999999 | N13: =+IF(L13=0,0,M13/L13) -> 1.04 | O13: =IF(J13-K13>0,J13-K13,0) -> 0 | P13: =IF(J13-K13<0,J13-K13,0) -> 0 | Q13: =+J13-K13 -> 0 | R13: =+O13+P13 -> 0 | S13: =+Q13-R13 -> 0
B15: =B13 -> Heka Invest - Actions | C15: Récap | D15: =+$K$1 -> 46022 | E15: =SUM(E5:E13) -> 14423076 | F15: =+IF(E15=0,0,G15/E15) -> 1.04 | G15: =SUM(G5:G13) -> 14999999 | H15: =SUM(H5:H13) -> 0 | I15: =+IF(H15=0,0,J15/H15) -> 0 | J15: =SUM(J5:J13) -> 0 | K15: =SUM(K5:K13) -> 0 | L15: =L13 -> 14423076 | M15: =+M13 -> 14999999 | N15: =+IF(L15=0,0,M15/L15) -> 1.04 | O15: =SUM(O5:O13) -> 0 | P15: =SUM(P5:P13) -> 0 | Q15: =+J15-K15 -> 0 | R15: =+O15+P15 -> 0 | S15: =+Q15-R15 -> 0
C16: Report | N16: =+IF(L16=0,0,M16/L16) -> 0 | O16: =IF(J16-K16>0,J16-K16,0) -> 0 | P16: =IF(J16-K16<0,J16-K16,0) -> 0 | Q16: =+J16-K16 -> 0 | R16: =+O16+P16 -> 0 | S16: =+Q16-R16 -> 0
B17: XX | F17: =IF(E17=0,0,G17/E17) -> 0 | I17: =IF(H17=0,0,J17/H17) -> 0 | K17: =+H17*N16 -> 0 | L17: =+L16+E17-H17 -> 0 | M17: =+M16+G17-K17 -> 0 | N17: =+IF(L17=0,0,M17/L17) -> 0 | O17: =IF(J17-K17>0,J17-K17,0) -> 0 | P17: =IF(J17-K17<0,J17-K17,0) -> 0 | Q17: =+J17-K17 -> 0 | R17: =+O17+P17 -> 0 | S17: =+Q17-R17 -> 0
B18: =B17 -> XX | F18: =IF(E18=0,0,G18/E18) -> 0 | I18: =IF(H18=0,0,J18/H18) -> 0 | K18: =+H18*N17 -> 0 | L18: =+L17+E18-H18 -> 0 | M18: =+M17+G18-K18 -> 0 | N18: =+IF(L18=0,0,M18/L18) -> 0 | O18: =IF(J18-K18>0,J18-K18,0) -> 0 | P18: =IF(J18-K18<0,J18-K18,0) -> 0 | Q18: =+J18-K18 -> 0 | R18: =+O18+P18 -> 0 | S18: =+Q18-R18 -> 0
B19: =B18 -> XX | F19: =IF(E19=0,0,G19/E19) -> 0 | I19: =IF(H19=0,0,J19/H19) -> 0 | K19: =+H19*N18 -> 0 | L19: =+L18+E19-H19 -> 0 | M19: =+M18+G19-K19 -> 0 | N19: =+IF(L19=0,0,M19/L19) -> 0 | O19: =IF(J19-K19>0,J19-K19,0) -> 0 | P19: =IF(J19-K19<0,J19-K19,0) -> 0 | Q19: =+J19-K19 -> 0 | R19: =+O19+P19 -> 0 | S19: =+Q19-R19 -> 0
B20: =B19 -> XX | F20: =IF(E20=0,0,G20/E20) -> 0 | I20: =IF(H20=0,0,J20/H20) -> 0 | K20: =+H20*N19 -> 0 | L20: =+L19+E20-H20 -> 0 | M20: =+M19+G20-K20 -> 0 | N20: =+IF(L20=0,0,M20/L20) -> 0 | O20: =IF(J20-K20>0,J20-K20,0) -> 0 | P20: =IF(J20-K20<0,J20-K20,0) -> 0 | Q20: =+J20-K20 -> 0 | R20: =+O20+P20 -> 0 | S20: =+Q20-R20 -> 0
B21: =+B20 -> XX | C21: Récap | D21: =+$K$1 -> 46022 | E21: =SUM(E16:E20) -> 0 | F21: =+IF(E21=0,0,G21/E21) -> 0 | G21: =SUM(G16:G20) -> 0 | H21: =SUM(H16:H20) -> 0 | I21: =+IF(H21=0,0,J21/H21) -> 0 | J21: =SUM(J16:J20) -> 0 | K21: =SUM(K16:K20) -> 0 | L21: =+L20 -> 0 | M21: =+M20 -> 0 | N21: =+IF(L21=0,0,M21/L21) -> 0 | O21: =SUM(O16:O20) -> 0 | P21: =SUM(P16:P20) -> 0 | Q21: =+J21-K21 -> 0 | R21: =+O21+P21 -> 0 | S21: =+Q21-R21 -> 0
B22: TOTAL | C22: Récap | D22: =+$K$1 -> 46022 | E22: =+SUM(E5:E21)/2 -> 14423076 | G22: =+SUM(G5:G21)/2 -> 14999999 | J22: =SUM(J5:J15)/2 -> 0 | K22: =SUM(K5:K15)/2 -> 0 | L22: =L15+L21 -> 14423076 | M22: =M15+M21 -> 14999999 | N22: =N15+N21 -> 1.04 | O22: =SUM(O5:O21)/2 -> 0 | P22: =SUM(P5:P21)/2 -> 0 | Q22: =+J22-K22 -> 0 | R22: =+O22+P22 -> 0 | S22: =SUM(S5:S15) -> 0
H23: Contrôle de cohérence | J23: Total PR achat - Total PR Vente | M23: =+G22-K22 -> 14999999 | N23: Comptabilité | S23: =IF(ABS(S22)>0.01,"ANOMALIE","OK") -> OK
J24: Ecart | M24: =+M22-M23 -> 0 | N24: Reprise PV/MV
J25: Inventaire PR | M25: =Inventaire!H30 -> 14999999 | N25: Ecart | O25: =O22-O23+O24 -> 0 | P25: =P22-P23+P24 -> 0
J26: Ecart | M26: =+M22-M25 -> 0 | N26: Contrôle | O26: =IF(ABS(O25)>0.01,"ANOMALIE","OK") -> OK | P26: =IF(ABS(P25)>0.01,"ANOMALIE","OK") -> OK
N27: Frais de transaction antérieurs :
N28: Ecart | O28: =O22+P22-O23-P23-O27 -> 0
O29: =IF(ABS(O28)<0.01,"OK","ANOMALIE") -> OK

Sheet Emprunt
B1: =Sommaire!A1 -> SANCY - SLP | G1: EMPRUNT AU | I1: =Sommaire!C1 -> 46022
B3: Emprunt caisse d'épargne haut de France | F3: Montant tiré
B4: Date de début de période | C4: Date de fin de période | D4: Durée | E4: Base | F4: Intitulé | G4: Mouvements | H4: Solde progressif | I4: marge | J4: Taux Euribor | K4: Intérêts payés | L4: Intérêts courus
G16: =SUM(G5:G15) -> 0 | K16: =SUM(K6:K15) -> 0 | L16: =SUM(L6:L15) -> 0
B19: Emprunt caisse d'épargne haut de France | F19: Montant non tiré
B20: Date de début de période | C20: Date de fin de période | D20: Durée | E20: Base | F20: Intitulé | G20: Mouvements | H20: Solde progressif | I20: Taux appliqué | J20: Intérêts | K20: Intérêts courus
G65: =G54 -> 0 | H65: =+H26 -> 0 | J65: =SUM(J22:J64) -> 0 | K65: =SUM(K57:K64) -> 0
J68: Intérêts courus | K68: =+K65+L16 -> 0
J69: Emprunt | K69: =+G16 -> 0

Sheet Intérêts CC
B1: =PVMV!B1 -> SANCY - SLP | E1: Compte courant | K1: =+Sommaire!C1 -> 46022
B6: Date de début de période | C6: Date de fin de période | D6: Intitulé | E6: Durée | F6: Base | G6: Mouvements | H6: Solde progressif | I6: Taux appliqué | J6: Intérêts | K6: Intérêts courus | L6: Intérêts réglés
B8: 45008 | C8: 45107 | D8: Apport | E8: =+C8-B8 -> 99 | F8: 365 | H8: =+G8+H7 -> 0 | J8: =ROUND((H8)*I8*E8/F8,2) -> 0 | K8: =J8 -> 0
E9: =+C9-B9 -> 0 | F9: 365 | H9: =+G9+H8 -> 0 | J9: =ROUND((H9)*I9*E9/F9,2) -> 0 | K9: =J9 -> 0
E10: =+C10-B10 -> 0 | F10: 365 | H10: =+G10+H9 -> 0 | J10: =ROUND((H10)*I10*E10/F10,2) -> 0 | K10: =J10 -> 0
E11: =+C11-B11 -> 0 | F11: 365 | H11: =+G11+H10 -> 0 | J11: =ROUND((H11)*I11*E11/F11,2) -> 0 | K11: =J11 -> 0
E12: =+C12-B12 -> 0 | F12: 365 | H12: =+G12+H11 -> 0 | J12: =ROUND((H12)*I12*E12/F12,2) -> 0 | K12: =J12 -> 0
E13: =+C13-B13 -> 0 | F13: 365 | H13: =+G13+H12 -> 0 | J13: =ROUND((H13)*I13*E13/F13,2) -> 0 | K13: =J13 -> 0
H14: =+G14+H13 -> 0
E15: =SUM(E8:E12) -> 99 | G15: =+G11 -> 0 | H15: =H14 -> 0 | J15: =SUM(J8:J14) -> 0 | K15: =SUM(K8:K14) -> 0 | L15: =SUM(L8:L12) -> 0
H16: Provision intérêts | I16: 1 | J16: =-J15 -> 0 | K16: =-K15 -> 0
H17: Inventaire | J17: =J15+J16 -> 0 | K17: =K15+K16 -> 0
B18: Taux d'intérêts : 5%
B19: L'Avance en Compte Courant devra être remboursée par la Société aux Associés-Prêteurs à la date du dixième anniversaire de la Date de Mise à Disposition (l'Échéance).
B20: échéance : 07/11/2022
B21: Nouvel échéance : 07/11/2032

Sheet Intérêts OC
B1: ='Intérêts CC'!B1 -> SANCY - SLP | I1: Intérêts courus | M1: =Sommaire!C1 -> 46022
F3: Capitalisation des intérêts au 05/10
B4: Date de début de période | C4: Date d'arrêté | D4: Durée | E4: Base | F4: Nominal | G4: INTERETS capitalisés | I4: INTERETS CAPITALISES cumulés | J4: Taux appliqué | K4: INTERETS | L4: Intérêts courus sur nominal | M4: Intérêts courus sur intérêts capitalisés | N4: Contrôle PR unitaire (int. Compris)
D5: =C5-B5 -> 0 | E5: 360 | J5: 0.08 | K5: =ROUND((F5+I5)*J5*D5/E5,2) -> 0 | L5: =+F5*D5*J5/E5 -> 0
D6: =C6-B6 -> 0 | E6: 360 | F6: =F5 -> 0 | I6: =G6+I5 -> 0 | J6: 0.08 | K6: =ROUND((F6+I6)*J6*D6/E6,2) -> 0 | L6: =+F6*D6*J6/E6 -> 0
D7: =+C7-B7 -> 0 | E7: 360 | F7: =F6 -> 0 | I7: =G7+I6 -> 0 | J7: 0.08 | K7: =ROUND((F7+I7)*J7*D7/E7,2) -> 0 | L7: =+F7*D7*J7/E7 -> 0 | M7: =+I7*D7*J7/E7 -> 0
D8: =+C8-B8 -> 0 | E8: 360 | F8: =F7 -> 0 | I8: =G8+I7 -> 0 | J8: 0.08 | K8: =ROUND((F8+I8)*J8*D8/E8,2) -> 0 | L8: =+F8*D8*J8/E8 -> 0 | M8: =+I8*D8*J8/E8 -> 0
D9: =+C9-B9 -> 0 | E9: 360 | F9: =F8 -> 0 | I9: =G9+I8 -> 0 | J9: 0.08 | K9: =ROUND((F9+I9)*J9*D9/E9,2) -> 0 | L9: =+F9*D9*J9/E9 -> 0 | M9: =+I9*D9*J9/E9 -> 0
D10: =+C10-B10 -> 0 | E10: 360 | F10: =F9 -> 0 | I10: =G10+I9 -> 0 | J10: 0.08 | K10: =ROUND((F10+I10)*J10*D10/E10,2) -> 0 | L10: =+F10*D10*J10/E10 -> 0 | M10: =+I10*D10*J10/E10 -> 0
D11: =+C11-B11 -> 0 | E11: 360 | F11: =F10 -> 0 | I11: =G11+I10 -> 0 | K11: =ROUND((F11+I11)*J11*D11/E11,2) -> 0 | L11: =+F11*D11*J11/E11 -> 0 | M11: =+I11*D11*J11/E11 -> 0
D12: =+C12-B12 -> 0 | E12: 360 | F12: =F11 -> 0 | I12: =G12+I11 -> 0 | K12: =ROUND((F12+I12)*J12*D12/E12,2) -> 0 | L12: =+F12*D12*J12/E12 -> 0 | M12: =+I12*D12*J12/E12 -> 0
D13: =+C13-B13 -> 0 | E13: 360 | F13: =F12 -> 0 | I13: =G13+I12 -> 0 | K13: =ROUND((F13+I13)*J13*D13/E13,2) -> 0 | L13: =+F13*D13*J13/E13 -> 0 | M13: =+I13*D13*J13/E13 -> 0
E14: 360 | F14: =F13 -> 0 | I14: =I13 -> 0
B15: Total | F15: =F14 -> 0 | G15: =SUM(G5:G14) -> 0 | I15: =I14 -> 0 | K15: =SUM(K5:K14) -> 0 | L15: =SUM(L5:L14) -> 0 | M15: =SUM(M5:M14) -> 0 | P15: =K15-L15-M15-G15 -> 0
B16: Date d'échéance : | F16: Provision 0% | G16: 0 | J16: Provision intérêts courus | K16: 0 | L16: 0 | M16: =-M15 -> 0 | P16: =IF(ABS(ROUND((P15),2))<=0.01,"Contrôle OK","Erreur") -> Contrôle OK
G17: =SUM(G15:G16) -> 0 | J17: Intérêts courus nets | L17: =SUM(L15:L16) -> 0 | M17: =SUM(M15:M16) -> 0
K21: Inventaire | L21: Contrôle
E22: Total intérêts courus | I22: =L17+M17 -> 0 | K22: =Inventaire!M18 -> 0 | L22: =IF(ROUND(I22,2)=ROUND(K22,2),"OK","ERREUR") -> OK
E23: Total intérêts capitalisés | I23: =G17 -> 0 | K23: =Inventaire!I18 -> 0 | L23: =IF(ROUND(I23,2)=ROUND(K23,2),"OK","ERREUR") -> OK

Sheet Sous-Rachat
B1: ='Liste porteurs selon versement '!A1 -> SANCY - SLP | D1: Suivi des Porteurs | F1: =Sommaire!C1 -> 46022
B2: Euro
D4: Nature opération
B5: Parts A | C5: 1000 | D5: TP | E5: Transfert de Parts
B6: Parts commandité | C6: 1000 | D6: ADF | E6: Appel de fonds
D7: DD | E7: Distribution définitive
D8: DB | E8: Distribition Bloquée | K8: Date opération
D9: DP | E9: Distribution provisoire | K9: %ADF
D10: RD | E10: Rappel de distribution | K10: Nature opération
D11: ENG | E11: Engagement supplémentaire | M11: TP | N11: ADF | O11: ADF | P11: DD | Q11: DB | R11: DP | S11: RD
F12: 45657 | M12: Transfert de parts 1T2025 | U12: =F1 -> 46022
D13: Engagement en Euros | E13: montant libéré | F13: Nombre de parts à date de situation | G13: Total des versements à date de situation | H13: % libéré | I13: reste a appeler | J13: Distribution | K13: Distribution en % | L13: Engagement à date de situation | M13: Mouvements de parts 1T2025 | N13: Affectation ADF | O13: ADF Test | P13: Distribution définitive Test | Q13: Distribution Bloqué Test | R13: Distribution provisoire Test | S13: Rappel de distribution Test | U13: Nombre de parts | V13: Total des versements | W13: % libéré | X13: Montant non appelé | Y13: Distribution | Z13: Distribution en % | AA13: Engagement Total
B14: Parts A
B16: Pantheon Global Private Credit Gt Fund, L.P. | C16: A | D16: 2306930 | E16: 2280038.1 | F16: =+D16/1000 -> 2306.93 | G16: 2280038.1 | H16: =+G16/L16 -> 0.988343 | I16: =L16-G16 -> 26891.88 | K16: =J16/D16 -> 0 | L16: 2306930 | U16: =F16+SUMIF($M$11:$T$11,"TP",$M16:$T16) -> 2306.93 | V16: =G16+SUMIF($M$11:$T$11,"ADF",$M16:$T16) -> 2280038.1 | W16: =IFERROR(V16/AA16,0) -> 0.988343 | X16: =AA16-V16 -> 26891.88 | Y16: =J16+SUMIF($M$11:$T$11,"DD",$M16:$T16)+SUMIF($M$11:$T$11,"DB",$M16:$T16)+SUMIF($M$11:$T$11,"DP",$M16:$T16)-SUMIF($M$11:$T$11,"RD",$M16:$T16) -> 0 | Z16: =Y16/AA16 -> 0 | AA16: =$C$5*U16 -> 2306930
B17: Pantheon Global Private Credit Ho Fund, L.P. | C17: A | D17: 1537960 | E17: 1520032 | F17: =+D17/1000 -> 1537.96 | G17: 1520032 | H17: =+G17/L17 -> 0.988343 | I17: =L17-G17 -> 17928 | K17: =J17/D17 -> 0 | L17: 1537960 | U17: =F17+SUMIF($M$11:$T$11,"TP",$M17:$T17) -> 1537.96 | V17: =G17+SUMIF($M$11:$T$11,"ADF",$M17:$T17) -> 1520032 | W17: =IFERROR(V17/AA17,0) -> 0.988343 | X17: =AA17-V17 -> 17928 | Y17: =J17+SUMIF($M$11:$T$11,"DD",$M17:$T17)+SUMIF($M$11:$T$11,"DB",$M17:$T17)+SUMIF($M$11:$T$11,"DP",$M17:$T17)-SUMIF($M$11:$T$11,"RD",$M17:$T17) -> 0 | Z17: =Y17/AA17 -> 0 | AA17: =$C$5*U17 -> 1537960
B18: Abacus Private Credit | C18: A | D18: 1264740 | E18: 1249996.9 | F18: =+D18/1000 -> 1264.74 | G18: 1249996.9 | H18: =+G18/L18 -> 0.988343 | I18: =L18-G18 -> 14743.07 | K18: =J18/D18 -> 0 | L18: 1264740 | U18: =F18+SUMIF($M$11:$T$11,"TP",$M18:$T18) -> 1264.74 | V18: =G18+SUMIF($M$11:$T$11,"ADF",$M18:$T18) -> 1249996.9 | W18: =IFERROR(V18/AA18,0) -> 0.988343 | X18: =AA18-V18 -> 14743.07 | Y18: =J18+SUMIF($M$11:$T$11,"DD",$M18:$T18)+SUMIF($M$11:$T$11,"DB",$M18:$T18)+SUMIF($M$11:$T$11,"DP",$M18:$T18)-SUMIF($M$11:$T$11,"RD",$M18:$T18) -> 0 | Z18: =Y18/AA18 -> 0 | AA18: =$C$5*U18 -> 1264740
B19: Mw River | C19: A | D19: 1770640 | E19: 1749999.6 | F19: =+D19/1000 -> 1770.64 | G19: 1749999.6 | H19: =+G19/L19 -> 0.988343 | I19: =L19-G19 -> 20640.35 | K19: =J19/D19 -> 0 | L19: 1770640 | U19: =F19+SUMIF($M$11:$T$11,"TP",$M19:$T19) -> 1770.64 | V19: =G19+SUMIF($M$11:$T$11,"ADF",$M19:$T19) -> 1749999.6 | W19: =IFERROR(V19/AA19,0) -> 0.988343 | X19: =AA19-V19 -> 20640.35 | Y19: =J19+SUMIF($M$11:$T$11,"DD",$M19:$T19)+SUMIF($M$11:$T$11,"DB",$M19:$T19)+SUMIF($M$11:$T$11,"DP",$M19:$T19)-SUMIF($M$11:$T$11,"RD",$M19:$T19) -> 0 | Z19: =Y19/AA19 -> 0 | AA19: =$C$5*U19 -> 1770640
B20: Eiger | C20: A | D20: 8436050 | E20: 8337711 | F20: =+D20/1000 -> 8436.05 | G20: 8337711 | H20: =+G20/L20 -> 0.988343 | I20: =L20-G20 -> 98339.03 | K20: =J20/D20 -> 0 | L20: 8436050 | U20: =F20+SUMIF($M$11:$T$11,"TP",$M20:$T20) -> 8436.05 | V20: =G20+SUMIF($M$11:$T$11,"ADF",$M20:$T20) -> 8337711 | W20: =IFERROR(V20/AA20,0) -> 0.988343 | X20: =AA20-V20 -> 98339.03 | Y20: =J20+SUMIF($M$11:$T$11,"DD",$M20:$T20)+SUMIF($M$11:$T$11,"DB",$M20:$T20)+SUMIF($M$11:$T$11,"DP",$M20:$T20)-SUMIF($M$11:$T$11,"RD",$M20:$T20) -> 0 | Z20: =Y20/AA20 -> 0 | AA20: =$C$5*U20 -> 8436050
B21: VI Advisory | C21: A | D21: 12650 | E21: 12502.54 | F21: =+D21/1000 -> 12.65 | G21: 12502.54 | H21: =+G21/L21 -> 0.98834308 | I21: =L21-G21 -> 147.46 | K21: =J21/D21 -> 0 | L21: 12650 | U21: =F21+SUMIF($M$11:$T$11,"TP",$M21:$T21) -> 12.65 | V21: =G21+SUMIF($M$11:$T$11,"ADF",$M21:$T21) -> 12502.54 | W21: =IFERROR(V21/AA21,0) -> 0.98834308 | X21: =AA21-V21 -> 147.46 | Y21: =J21+SUMIF($M$11:$T$11,"DD",$M21:$T21)+SUMIF($M$11:$T$11,"DB",$M21:$T21)+SUMIF($M$11:$T$11,"DP",$M21:$T21)-SUMIF($M$11:$T$11,"RD",$M21:$T21) -> 0 | Z21: =Y21/AA21 -> 0 | AA21: =$C$5*U21 -> 12650
B22: AMER PARTNERS | C22: A | D22: 37940 | E22: 37497.73 | F22: =+D22/1000 -> 37.94 | G22: 37497.73 | H22: =+G22/L22 -> 0.98834291 | I22: =L22-G22 -> 442.27 | K22: =J22/D22 -> 0 | L22: 37940 | U22: =F22+SUMIF($M$11:$T$11,"TP",$M22:$T22) -> 37.94 | V22: =G22+SUMIF($M$11:$T$11,"ADF",$M22:$T22) -> 37497.73 | W22: =IFERROR(V22/AA22,0) -> 0.98834291 | X22: =AA22-V22 -> 442.27 | Y22: =J22+SUMIF($M$11:$T$11,"DD",$M22:$T22)+SUMIF($M$11:$T$11,"DB",$M22:$T22)+SUMIF($M$11:$T$11,"DP",$M22:$T22)-SUMIF($M$11:$T$11,"RD",$M22:$T22) -> 0 | Z22: =Y22/AA22 -> 0 | AA22: =$C$5*U22 -> 37940
B23: KTALYST INVESTMENTS | C23: A | D23: 12650 | E23: 12502.54 | F23: =+D23/1000 -> 12.65 | G23: 12502.54 | H23: =+G23/L23 -> 0.98834308 | I23: =L23-G23 -> 147.46 | K23: =J23/D23 -> 0 | L23: 12650 | U23: =F23+SUMIF($M$11:$T$11,"TP",$M23:$T23) -> 12.65 | V23: =G23+SUMIF($M$11:$T$11,"ADF",$M23:$T23) -> 12502.54 | W23: =IFERROR(V23/AA23,0) -> 0.98834308 | X23: =AA23-V23 -> 147.46 | Y23: =J23+SUMIF($M$11:$T$11,"DD",$M23:$T23)+SUMIF($M$11:$T$11,"DB",$M23:$T23)+SUMIF($M$11:$T$11,"DP",$M23:$T23)-SUMIF($M$11:$T$11,"RD",$M23:$T23) -> 0 | Z23: =Y23/AA23 -> 0 | AA23: =$C$5*U23 -> 12650
B24: TOTAL PARTS A | C24: A1 | D24: =SUM(D16:D23) -> 15379560 | E24: =SUM(E16:E23) -> 15200280 | F24: =SUM(F16:F23) -> 15379.56 | G24: =SUM(G16:G23) -> 15200280 | H24: =+G24/L24 -> 0.988343 | I24: =SUM(I16:I23) -> 179279.52 | J24: =SUM(J16:J23) -> 0 | K24: =J24/D24 -> 0 | L24: =SUM(L16:L23) -> 15379560 | U24: =SUM(U16:U23) -> 15379.56 | V24: =SUM(V16:V23) -> 15200280 | W24: =V24/AA24 -> 0.988343 | X24: =SUM(X16:X23) -> 179279.52 | Y24: =SUM(Y16:Y23) -> 0 | AA24: =SUM(AA16:AA23) -> 15379560
B28: Part de Commandité | C28: Commandité | D28: 1000 | E28: 988.34 | F28: 1 | G28: 988.34 | H28: =+G28/L28 -> 0.98834 | I28: =D28-G28 -> 11.66 | K28: =J28/D28 -> 0 | L28: =D28 -> 1000 | U28: =F28+SUMIF($M$11:$T$11,"TP",$M28:$T28) -> 1 | V28: =G28+SUMIF($M$11:$T$11,"ADF",$M28:$T28) -> 988.34 | W28: =IFERROR(V28/AA28,0) -> 0.98834 | X28: =AA28-V28 -> 11.66 | Y28: =J28+SUMIF($M$11:$T$11,"DD",$M28:$T28)+SUMIF($M$11:$T$11,"DB",$M28:$T28)+SUMIF($M$11:$T$11,"DP",$M28:$T28)-SUMIF($M$11:$T$11,"RD",$M28:$T28) -> 0 | Z28: =Y28/AA28 -> 0 | AA28: =$C$5*U28 -> 1000
B29: Total PARTS Commandité | D29: =D28 -> 1000 | E29: =SUM(E28) -> 988.34 | F29: =F28 -> 1 | G29: =G28 -> 988.34 | H29: =H28 -> 0.98834 | I29: =I28 -> 11.66 | J29: =J28 -> 0 | K29: =K28 -> 0 | L29: =L28 -> 1000 | U29: =U28 -> 1 | V29: =V28 -> 988.34 | W29: =IFERROR(V29/AA29,0) -> 0.98834 | X29: =X28 -> 11.66 | Y29: =Y28 -> 0 | Z29: =Y29/AA29 -> 0 | AA29: =AA28 -> 1000
B31: TOTAL PARTS | D31: =D24+D29 -> 15380560 | E31: =+E24+E29 -> 15201269 | F31: =+F29+F24 -> 15380.56 | G31: =+G29+G24 -> 15201269 | H31: =E31/D31 -> 0.988343 | I31: =+I29+I24 -> 179291.18 | J31: =+J29+J24 -> 0 | K31: =J31/D31 -> 0 | L31: =+L29+L24 -> 15380560 | U31: =U24+U29 -> 15380.56 | V31: =V24+V29 -> 15201269 | W31: =V31/AA31 -> 0.988343 | X31: =X24+X29 -> 179291.18 | Y31: =Y24+Y29 -> 0 | AA31: =AA24+AA29 -> 15380560

Sheet Liste porteurs selon versement 
A1: =Inventaire!B1 -> SANCY - SLP | C1: Liste des porteurs | E1: =Sommaire!C1 -> 46022
B4: Type de parts | C4: Nbre de parts | D4: VL
B5: A | C5: =Inventaire!F8 -> 15379.56 | D5: =Inventaire!F9 -> 745.47027
B6: Commandité | C6: =Inventaire!G8 -> 1 | D6: =Inventaire!G9 -> 745.47027
A9: Souscripteurs | B9: Type de parts | C9: Nb de parts soucrites | D9: Valeur unitaire | E9: Evaluation
A10: ='Sous-Rachat'!B16 -> Pantheon Global Private Credit Gt Fund, L.P. | B10: =VLOOKUP(A10,'Sous-Rachat'!$B$16:$C$24,2,FALSE) -> A | C10: =VLOOKUP(A10,'Sous-Rachat'!$B$16:$F$24,5,FALSE) -> 2306.93 | D10: =VLOOKUP(B10,$B$5:$D$6,3,FALSE) -> 745.47027 | E10: =C10*D10 -> 1719747.7
A11: Total Pantheon Global Private Credit Gt Fund, L.P. | E11: =SUBTOTAL(9,E10:E10) -> 1719747.7
A12: ='Sous-Rachat'!B17 -> Pantheon Global Private Credit Ho Fund, L.P. | B12: =VLOOKUP(A12,'Sous-Rachat'!$B$16:$C$24,2,FALSE) -> A | C12: =VLOOKUP(A12,'Sous-Rachat'!$B$16:$F$24,5,FALSE) -> 1537.96 | D12: =VLOOKUP(B12,$B$5:$D$6,3,FALSE) -> 745.47027 | E12: =C12*D12 -> 1146503.5
A13: Total Pantheon Global Private Credit Ho Fund, L.P. | E13: =SUBTOTAL(9,E12:E12) -> 1146503.5
A14: ='Sous-Rachat'!B18 -> Abacus Private Credit | B14: =VLOOKUP(A14,'Sous-Rachat'!$B$16:$C$24,2,FALSE) -> A | C14: =VLOOKUP(A14,'Sous-Rachat'!$B$16:$F$24,5,FALSE) -> 1264.74 | D14: =VLOOKUP(B14,$B$5:$D$6,3,FALSE) -> 745.47027 | E14: =C14*D14 -> 942826.07
A15: Total Abacus Private Credit | E15: =SUBTOTAL(9,E14:E14) -> 942826.07
A16: ='Sous-Rachat'!B19 -> Mw River | B16: =VLOOKUP(A16,'Sous-Rachat'!$B$16:$C$24,2,FALSE) -> A | C16: =VLOOKUP(A16,'Sous-Rachat'!$B$16:$F$24,5,FALSE) -> 1770.64 | D16: =VLOOKUP(B16,$B$5:$D$6,3,FALSE) -> 745.47027 | E16: =C16*D16 -> 1319959.5
A17: Total Bow River | E17: =SUBTOTAL(9,E16:E16) -> 1319959.5
A18: ='Sous-Rachat'!B20 -> Eiger | B18: =VLOOKUP(A18,'Sous-Rachat'!$B$16:$C$24,2,FALSE) -> A | C18: =VLOOKUP(A18,'Sous-Rachat'!$B$16:$F$24,5,FALSE) -> 8436.05 | D18: =VLOOKUP(B18,$B$5:$D$6,3,FALSE) -> 745.47027 | E18: =C18*D18 -> 6288824.5
A19: Total Eiger | E19: =SUBTOTAL(9,E18:E18) -> 6288824.5
A20: ='Sous-Rachat'!B21 -> VI Advisory | B20: =VLOOKUP(A20,'Sous-Rachat'!$B$16:$C$24,2,FALSE) -> A | C20: =VLOOKUP(A20,'Sous-Rachat'!$B$16:$F$24,5,FALSE) -> 12.65 | D20: =VLOOKUP(B20,$B$5:$D$6,3,FALSE) -> 745.47027 | E20: =C20*D20 -> 9430.1989
A21: Total VI Advisory | E21: =SUBTOTAL(9,E20:E20) -> 9430.1989
A22: ='Sous-Rachat'!B22 -> AMER PARTNERS | B22: =VLOOKUP(A22,'Sous-Rachat'!$B$16:$C$24,2,FALSE) -> A | C22: =VLOOKUP(A22,'Sous-Rachat'!$B$16:$F$24,5,FALSE) -> 37.94 | D22: =VLOOKUP(B22,$B$5:$D$6,3,FALSE) -> 745.47027 | E22: =C22*D22 -> 28283.142
A23: Total AMER PARTNERS | E23: =SUBTOTAL(9,E22:E22) -> 28283.142
A24: ='Sous-Rachat'!B23 -> KTALYST INVESTMENTS | B24: =VLOOKUP(A24,'Sous-Rachat'!$B$16:$C$24,2,FALSE) -> A | C24: =VLOOKUP(A24,'Sous-Rachat'!$B$16:$F$24,5,FALSE) -> 12.65 | D24: =VLOOKUP(B24,$B$5:$D$6,3,FALSE) -> 745.47027 | E24: =C24*D24 -> 9430.1989
A25: Total KTALYST INVESTMENTS | E25: =SUBTOTAL(9,E24:E24) -> 9430.1989
A26: ='Sous-Rachat'!B28 -> Part de Commandité | B26: =VLOOKUP(A26,'Sous-Rachat'!$B$28:$C$28,2,FALSE) -> Commandité | C26: =VLOOKUP(A26,'Sous-Rachat'!$B$28:$F$28,5,FALSE) -> 1 | D26: =VLOOKUP(B26,$B$5:$D$7,3,FALSE) -> 745.47027 | E26: =C26*D26 -> 745.47027
A27: Total Parts Commandité | E27: =SUBTOTAL(9,E26:E26) -> 745.47027
A28: Total général | E28: =SUBTOTAL(9,E10:E26) -> 11465750
D31: =C32-E36 -> 0
B32: Nombre de parts | C32: =SUM(C10:C26) -> 15380.56 | D32: =+IF(C32=E36,"OK","Anomalie") -> OK
C33: Actif net selon inventaire | E33: =Inventaire!C7 -> 11465750
C35: Actif net non affecté | E35: =+E33-E28 -> 0.01480992
C36: Nombre de parts | E36: =SUM(C5:C7) -> 15380.56
C37: Ecart/part | E37: =+E35/E36 -> 9.6289859e-07
C38: Conclusion | E38: =IF(ABS(E37)<0.01,"OK","Anomalie") -> OK

Sheet Frais de gestion
B1: =+Inventaire!B1 -> SANCY - SLP | F1: Frais de gestion | H1: =Sommaire!C1 -> 46022
B4: Frais de gestion de la société de gestion | H4: Charges
B5: Rémunération de la société de gestion
B13: Sous-total frais de gestion de la société de gestion | H13: =SUM(H5:H12) -> 0
B16: Autres frais de gestion | C16: Base de calcul | D16: Prorata temporis | E16: Taux | F16: TVA | G16: Calcul provisions | H16: Charges comptabilisés
B17: Honoraires CAC
B18: Budget 2025 3 660€ HT / an
B19: Provision 1T2025 | C19: 3435 | D19: 0.25 | F19: 1.2 | G19: =C19*D19*F19 -> 1030.5
B20: Provision 2T2025 | C20: =C19 -> 3435 | D20: 0.25 | F20: 1.2 | G20: =C20*D20*F20 -> 1030.5
B21: Provision 3T2025 | C21: =C20 -> 3435 | D21: 0.25 | F21: 1.2 | G21: =C21*D21*F21 -> 1030.5 | H21: =G21 -> 1030.5
B22: Provision 4T2025 | C22: 3660 | D22: 0.25 | F22: 1.2 | G22: =C22*D22*F22 -> 1098 | H22: =G22 -> 1098
B24: Facture 1S2025 | H24: 2151
B25: Provision complémentaire 1S2025 | H25: 112.5
H28: =SUM(H19:H27) -> 4392
B29: Honoraires comptables - Aplitec
B30: AIFM budget 2025 428€ HT /an
B31: Facture AIFM 1T2025 | C31: 424 | D31: 0.25 | E31: 0.3 | F31: N/A | G31: =C31*D31 -> 106 | H31: =G31 -> 106
B32: Facture AIFM 2T2025 | C32: 428 | D32: 0.25 | E32: 0.3 | F32: N/A | G32: =C32*D32 -> 107 | H32: =G32 -> 107
B33: Facture AIFM 3T2025 | C33: 428 | D33: 0.25 | E33: 0.3 | F33: N/A | G33: =C33*D33 -> 107 | H33: =G33 -> 107
B34: Provision AIFM 4T2025 | C34: 428 | D34: 0.25 | E34: 0.3 | F34: N/A | G34: =C34*D34 -> 107 | H34: 107
B35: Tenue Comptable budget 2025 5 440€ HT /an
B36: Facture VL 1T2025 | C36: 5400 | D36: 0.25 | F36: N/A | G36: =C36*D36 -> 1350 | H36: =G36 -> 1350
B37: Facture VL 2T2025 | C37: 5440 | D37: 0.25 | F37: N/A | G37: =C37*D37 -> 1360 | H37: =G37 -> 1360
B38: Facture VL 3T2025 | C38: 5440 | D38: 0.25 | F38: N/A | G38: =C38*D38 -> 1360 | H38: =G38 -> 1360
B39: Provision VL 4T2025 | C39: 5440 | D39: 0.25 | F39: N/A | G39: =C39*D39 -> 1360 | H39: 1360
B40: Déclaration BDF budget 2025 440€ HT /an
B41: Facture BDF 1T2025 | C41: 400 | D41: 0.25 | F41: N/A | G41: =C41*D41 -> 100 | H41: =G41 -> 100
B42: Facture BDF 2T2025 | C42: 440 | D42: 0.25 | F42: N/A | G42: =C42*D42 -> 110 | H42: =G42 -> 110
B43: Facture BDF 3T2025 | C43: 440 | D43: 0.25 | F43: N/A | G43: =C43*D43 -> 110 | H43: =G43 -> 110
B44: Provision BDF 4T2025 | C44: 440 | D44: 0.25 | F44: N/A | G44: =C44*D44 -> 110 | H44: 110
B45: Dépôt VL Base GECO Budget 2024 280€ HT /an
B46: Facture dépôt VL 1T2025 | C46: 280 | D46: 0.25 | G46: =C46*D46 -> 70 | H46: =+G46 -> 70
B47: Facture dépôt VL 2T2025 | C47: 280 | D47: 0.25 | G47: =C47*D47 -> 70 | H47: =+G47 -> 70
B48: Facture dépôt VL 3T2025 | C48: 280 | D48: 0.25 | G48: =C48*D48 -> 70 | H48: =+G48 -> 70
B49: Provision dépôt VL 4T2025 | C49: 280 | D49: 0.25 | G49: =C49*D49 -> 70 | H49: =+G49 -> 70
H52: =SUM(H31:H51) -> 6567
B53: Frais de dépositaire
B54: Budget minimum 10 000 HT par an | J54: Actif net
C55: 10000 | D55: 0.25 | F55: 1.2 | G55: =C55*D55*F55 -> 3000 | J55: =Inventaire!C7 -> 11465750
B56: Distribution (500€ HT par distribution) | C56: 500 | F56: 1.2 | G56: =C56*D56*F56 -> 0
...

Sheet Créances_&_dettes
B1: =+Inventaire!B1 -> SANCY - SLP | D1: Créances et dettes : | G1: =Sommaire!C1 -> 46022
B4: Créances | G4: =G1 -> 46022
B6: Refacturation EMZ
B9: Crédit vendeur
C10: Nominal crédit vendeur | G10: 0 | J10: Compte 46220010
C11: Intérêt crédit vendeur | G11: 0 | J11: Compte 46220011
B13: TOTAL | G13: =SUM(G6:G12) -> 0
B16: Dettes | G16: =G1 -> 46022
B18: EMZ Partners
F22: Solde | G22: =SUM(G19:G20) -> 0
B23: Honoraires CAC - Deloitte
B24: Provision 2T2025 - Solde | G24: 112.5
B25: Provision 3T2025 | G25: 1030.5
B26: Provision 4T2025 | G26: 1098
F28: Solde | G28: =SUM(G24:G27) -> 2241
B29: Honoraires comptables - Avant reprise
F34: Solde | G34: =SUM(G30:G33) -> 0
B35: Honoraires comptables - APLITEC
B36: Provision AIFM 4T2025 | G36: 107
B37: Provision VL 4T2025 | G37: 1360
B38: Provision BDF 4T2025 | G38: 110
B39: Provision dépôt VL 4T2025 | G39: 70
F41: =F28 -> Solde | G41: =SUM(G36:G40) -> 1647
B42: Honoraires dépositaire - CACEIS
B43: Provision 3T2025 | G43: 3000
