Workbook
Name _zz8: #REF!
Name _zz8: #REF!
Name _zz8: #REF!
Name ABCcostPerLine: [3]Assump!$O$77
Name ABCcostPerLine: #REF!
Name ABCcostPerLine: #REF!
Name ABCcostPerLine: #REF!
Name ABClinesMax: [3]Assump!$L$77
Name ABClinesMax: #REF!
Name ABClinesMax: #REF!
Name ABClinesMax: #REF!
Name ABClinesMin: [3]Assump!$M$77
Name ABClinesMin: #REF!
Name ABClinesMin: #REF!
Name ABClinesMin: #REF!
Name ABCterminalCost: [3]Assump!$O$79
Name ABCterminalCost: #REF!
Name ABCterminalCost: #REF!
Name ABCterminalCost: #REF!
Name ABCutil: [3]Assump!$N$77
Name ABCutil: #REF!
Name ABCutil: #REF!
Name ABCutil: #REF!
Name AccessNodeSize: [3]Assump!$L$103
Name AccessNodeSize: #REF!
Name AccessNodeSize: #REF!
Name AccessNodeSize: #REF!
Name ActCabinetTelcoCost: [3]Assump!$N$106
Name ActCabinetTelcoCost: #REF!
Name ActCabinetTelcoCost: #REF!
Name ActCabinetTelcoCost: #REF!
Name ActCabinetVideoCost: [3]Assump!$N$107
Name ActCabinetVideoCost: #REF!
Name ActCabinetVideoCost: #REF!
Name ActCabinetVideoCost: #REF!
Name ActiveLines: [3]Assump!$L$106
Name ActiveLines: #REF!
Name ActiveLines: #REF!
Name ActiveLines: #REF!
Name ActiveUtil: [3]Assump!$M$106
Name ActiveUtil: #REF!
Name ActiveUtil: #REF!
Name ActiveUtil: #REF!
Name AN0: 'Frais de gestion'!$H$144
Name AreaPerEmployee: [3]Assump!$L$69
Name AreaPerEmployee: #REF!
Name AreaPerEmployee: #REF!
Name AreaPerEmployee: #REF!
Name AreaPerHeadend: [3]Assump!$L$71
Name AreaPerHeadend: #REF!
Name AreaPerHeadend: #REF!
Name AreaPerHeadend: #REF!
Name AreaPerSwitch: [3]Assump!$L$70
Name AreaPerSwitch: #REF!
Name AreaPerSwitch: #REF!
Name AreaPerSwitch: #REF!
Name ArialCoaxLabor: [3]Assump!$M$134
Name ArialCoaxLabor: #REF!
Name ArialCoaxLabor: #REF!
Name ArialCoaxLabor: #REF!

Sheet Sommaire
A1: BOLZEN - SLP | C1: 46022
A3: Code AMF | B3: FDS104360
A5: Méthode de comptabilisation des intérêts | B5: Coupon couru
A7: Particularités de la SLP
A9: Fonds investi | B9: Le Fonds interviendra dans des opérations conformes à la politique d'investissement d'EMZ 11 et à titre principal au titre de toute opération de financement obligataire ou unitranche, pouvant prendre des formes multiples, dont notamment des obligations à bons de souscription d'actions, des obligations convertibles, des obligations remboursables en actions, des obligations simples, ou tout autre type d'obligations. | D9: Article 2.6
A11: Périodicité de la VL | B11: Trimestrielle, au 31 mars, 30 juin, 30 septembre et 31 décembre. | D11: Article 14
A13: Date de clôture du premier exercice comptable | B13: 46022 | D13: Article 21
A15: Type de parts
A16: Parts A1 | B16: Investisseurs avertis
A17: Parts A2 | B17: Investisseurs avertis
A18: Parts de Commandité | B18: Parts associés commandités
A20: Frais de gestion | B20: La société de Gestion ne recevra pas de commission de la part du Fonds | D20: Article 20.1.1
A22: Dépositaire | B22: Caceis
A24: CAC | B24: Deloitte
A28: Evaluation des OPC | B28: dernière VL connue
A30: Devise de comptabilisation | B30: Euro
A33: Zone de saisie
A38: Onglets | B38: Synthèse contrôles
A39: Inventaire | B39: =Inventaire!F12
A40: Calcul VL | B40: ='Calcul VL'!G6 -> OK
A41: OD Rééval | B41: =IF(AND('O.D Rééval'!G38="OK",'O.D Rééval'!G80="OK",'O.D Rééval'!G107="OK"),"OK","Anomalies") -> OK
A42: Rappro titres | B42: ='Rappro Titres & Parts'!C25 -> OK
B43: ='Rappro Titres & Parts'!F21 -> OK
B44: ='Rappro Titres & Parts'!I21 -> OK
A45: Intérêts OC | B45: ='Intérêts Obligations'!J105 -> OK
B46: ='Intérêts Obligations'!J106 -> OK
A47: PVMV | B47: =PVMV!M167 -> OK
A48: PV | B48: =PVMV!O165 -> OK
A49: MV | B49: =PVMV!P165 -> OK
B50: =PVMV!S163 -> OK
B51: =PVMV!O173 -> OK
A52: Liste porteurs selon versement | B52: ='Liste porteurs selon versement '!F25 -> OK
B53: ='Liste porteurs selon versement '!E18 -> OK
A54: Frais de gestion | B54: ='Frais de gestion'!J126 -> OK
A55: Résultat | B55: =Résultat!H194 -> OK
A56: N-1 | B56: =Résultat!I194 -> OK
A57: Bilan | B57: =Bilan!I101 -> OK
A58: N-1 | B58: =Bilan!J101 -> OK
A59: Variation actif net après valorisation | B59: =IF(B39="",'Capitaux propres'!D37,"") -> OK
A60: N-1 | B60: ='Capitaux propres'!E37 -> OK
...

Sheet Inventaire
B1: =Sommaire!A1 -> BOLZEN - SLP | G1: Inventaire au : | H1: =Sommaire!C1 -> 46022
B2: Code ISIN parts A1 | C2: ='Calcul VL'!A8 -> FR001400XME8
B3: Code ISIN parts A2 | C3: ='Calcul VL'!A9 -> FR001400XMF5
B4: Code ISIN parts Commandité | C4: ='Calcul VL'!A10 -> FR001400XMG3
B7: Actif net : | C7: =ROUNDDOWN(D74,2) -> 90063591 | D7: Type de parts : | E7: Total | F7: A1 | G7: A2 | H7: Part de Commandité
B8: Actif net fonds général : | C8: =+D74 -> 90063591 | D8: Nbre de parts : | E8: =SUM(F8:H8) -> 943269.7 | F8: ='Calcul VL'!C8 -> 943268.7 | G8: ='Calcul VL'!C9 -> 0 | H8: ='Calcul VL'!C10 -> 1
D9: valeur liquidative : | F9: ='Calcul VL'!F8 -> 95.480211 | G9: ='Calcul VL'!F9 -> 0 | H9: ='Calcul VL'!F10 -> 95.480211
A11: G ou I | B11: Code Titre | C11: Libellé | D11: Quantité | E11: Prix de revient unitaire | F11: Cours | G11: Date de valorisation | H11: Prix de revient | I11: Intérêt ou dividendes capitalisés Prime de non conversion | J11: Prix de revient global | K11: Valeur d'estimation hors coupons | L11: +/- value potentielle | M11: Coupon couru / Dividende | N11: Valeur d'estimation coupon inclus | O11: % actif net | Q11: Valo Aplitec au 31/12/2025 | R11: Valo SG au 31/12/2025 | S11: écart | T11: Cours unitaire de valorisation
B12: FONDS GENERAL | F12: =IF('Rappro Balance'!G22=0,"","Anomalie de valorisation")
B13: Instruments financiers de capital Investissement
A15: G | B15: FROREUR02773 | C15: =PVMV!B35 -> Inflexion BIDCO - ORADP 1 | D15: =PVMV!L35 -> 10080000 | E15: =PVMV!F35 -> 1 | F15: 1 | G15: =G16 -> 46022 | H15: =PVMV!M35 -> 10080000 | J15: =H15+I15 -> 10080000 | K15: =ROUND(F15*D15,2) -> 10080000 | L15: =ROUND(+K15-J15,2) -> 0 | N15: =K15+M15 -> 10080000 | O15: =+N15/$D$74*100 -> 11.192092 | Q15: =N15 -> 10080000 | R15: 10080000 | S15: =Q15-R15 -> 0 | T15: =(R15-M15)/D15 -> 1
A16: G | B16: FROCEUR02774 | C16: =PVMV!B20 -> Inflexion BIDCO - OCADP 2 | D16: =PVMV!L20 -> 40320000 | E16: =PVMV!F20 -> 1 | F16: 1 | G16: =H1 -> 46022 | H16: =PVMV!M20 -> 40320000 | I16: ='Intérêts Obligations'!G21 -> 0 | J16: =H16+I16 -> 40320000 | K16: =ROUND(F16*D16,2) -> 40320000 | L16: =ROUND(+K16-J16,2) -> 0 | M16: ='Intérêts Obligations'!L23 -> 1712219.2 | N16: =K16+M16 -> 42032219 | O16: =+N16/$D$74*100 -> 46.669491 | Q16: =N16 -> 42032219 | R16: 42032219 | S16: =Q16-R16 -> 0 | T16: =(R16-M16)/D16 -> 1
A18: G | B18: DEADEUR03287 | C18: =PVMV!B40 -> Koenig solutions - ADP B | D18: =PVMV!L40 -> 87200 | E18: =PVMV!F40 -> 100 | F18: 100.77917 | G18: =G16 -> 46022 | H18: =PVMV!M40 -> 8720000 | I18: ='Intérêts Obligations'!G44 -> 0 | J18: =H18+I18 -> 8720000 | K18: =ROUND(F18*D18,2) -> 8787943.3 | L18: =ROUND(+K18-J18,2) -> 67943.33 | M18: ='Intérêts Obligations'!L46 -> 90591.11 | N18: =K18+M18 -> 8878534.4 | O18: =+N18/$D$74*100 -> 9.8580729 | Q18: =N18 -> 8878534.4 | R18: 8878534.4 | S18: =Q18-R18 -> 0 | T18: =(R18-M18)/D18 -> 100.77917
A19: G | B19: DEOCEUR03288 | C19: =PVMV!B45 -> Koenig solutions - OC (SHL) | D19: =PVMV!L45 -> 3200 | E19: =PVMV!F45 -> 8175 | F19: 8238.6969 | G19: =G18 -> 46022 | H19: =PVMV!M45 -> 26160000 | I19: ='Intérêts Obligations'!G60 -> 0 | J19: =H19+I19 -> 26160000 | K19: =ROUND(F19*D19,2) -> 26363830 | L19: =ROUND(+K19-J19,2) -> 203830 | M19: ='Intérêts Obligations'!L62 -> 0 | N19: =K19+M19 -> 26363830 | O19: =+N19/$D$74*100 -> 29.272462 | Q19: =N19 -> 26363830 | R19: 26363830 | S19: =Q19-R19 -> 0 | T19: =(R19-M19)/D19 -> 8238.6969
A20: G | B20: DEOCEUR03289 | C20: =PVMV!B51 -> Koenig solutions - OC (Warehouse II - ADP A) | D20: =PVMV!L51 -> 500 | E20: =PVMV!F51 -> 1000 | F20: 1046.0204 | G20: =G19 -> 46022 | H20: =PVMV!M51 -> 500000 | I20: ='Intérêts Obligations'!G75 -> 0 | J20: =H20+I20 -> 500000 | K20: =ROUND(F20*D20,2) -> 523010.18 | L20: =ROUND(+K20-J20,2) -> 23010.18 | M20: ='Intérêts Obligations'!L77 -> 0 | N20: =K20+M20 -> 523010.18 | O20: =+N20/$D$74*100 -> 0.58071211 | Q20: =N20 -> 523010.18 | R20: 523010.18 | S20: =Q20-R20 -> 0 | T20: =(R20-M20)/D20 -> 1046.0204
A22: G | B22: FROSEUR03290 | C22: =PVMV!B56 -> SNIC Technologies Group - OBSA | D22: =PVMV!L56 -> 63750000 | E22: =PVMV!F56 -> 1 | F22: 1 | G22: =G20 -> 46022 | H22: =PVMV!M56 -> 63750000 | I22: ='Intérêts Obligations'!G98 -> 0 | J22: =H22+I22 -> 63750000 | K22: =ROUND(F22*D22,2) -> 63750000 | L22: =ROUND(+K22-J22,2) -> 0 | M22: ='Intérêts Obligations'!L100 -> 247916.67 | N22: =K22+M22 -> 63997917 | O22: =+N22/$D$74*100 -> 71.058589 | Q22: =N22 -> 63997917 | R22: 63997917 | S22: =Q22-R22 -> 0 | T22: =(R22-M22)/D22 -> 1
C25: Total | H25: =SUM(H14:H24) -> 149530000 | I25: =SUM(I14:I24) -> 0 | J25: =SUM(J14:J24) -> 149530000 | K25: =SUM(K14:K24) -> 1.4982478e+08 | L25: =SUM(L14:L24) -> 294783.51 | M25: =SUM(M14:M24) -> 2050727 | N25: =SUM(N14:N24) -> 1.5187551e+08 | O25: =SUM(O15:O24) -> 168.63142 | Q25: =SUM(Q15:Q24) -> 1.5187551e+08 | R25: =SUM(R15:R24) -> 1.5187551e+08 | S25: =SUM(S15:S24) -> 0 | T25: Total
B26: Autres instruments financiers
C29: Total | I29: =SUM(I26:I28) -> 0 | K29: =SUM(K26:K28) -> 0 | L29: =SUM(L26:L28) -> 0 | M29: =SUM(M26:M28) -> 0 | N29: =SUM(N26:N28) -> 0 | O29: =SUM(O26:O28) -> 0
C31: Total fonds général | H31: =+H25+H29 -> 149530000 | I31: =+I25+I29 -> 0 | J31: =+J25+J29 -> 149530000 | K31: =+K25+K29 -> 1.4982478e+08 | L31: =+L25+L29 -> 294783.51 | M31: =+M25+M29 -> 2050727 | N31: =+N25+N29 -> 1.5187551e+08 | O31: =+O25+O29 -> 168.63142
B34: Total inventaire : | H34: =H31 -> 149530000 | I34: =I31 -> 0 | J34: =J31 -> 149530000 | K34: =K31 -> 1.4982478e+08 | L34: =L31 -> 294783.51 | M34: =M31 -> 2050727 | N34: =N31 -> 1.5187551e+08 | O34: =+O31 -> 168.63142
B39: Composition de l'actif net | D39: Fonds général | E39: %
B41: Inventaire | D41: =N34 -> 1.5187551e+08 | E41: =+D41/$D$74 -> 1.6863142
B43: Disponibilités | D43: ='Rappro Banque'!C30 -> 2114169.8 | E43: =+D43/$D$74 -> 0.023474189
B45: Créances | D45: =+'Créances_&_dettes'!G35 -> 0 | E45: =+D45/$D$74 -> 0
B47: Dettes | D47: =-'Créances_&_dettes'!G103+'Créances_&_dettes'!G105-'Créances_&_dettes'!G106 -> -63484.78 | E47: =+D47/$D$74 -> -0.0007048884
B49: Dettes financières | D49: =-(Emprunt!K186+Emprunt!K187) -> -63862605 | E49: =+D49/$D$74 -> -0.70908348
B51: Actif net | D51: =ROUND(SUM(D41:D50),2) -> 90063591 | E51: =SUM(E40:E50) -> 1
B62: Composition de l'actif net (2) | D62: Fonds général | E62: Reemploi/Compte bloqué/Clawback | F62: Reinvestissement | G62: Total | H62: %
B64: Inventaire BDF | D64: =D41 -> 1.5187551e+08 | G64: =D64+E64+F64 -> 1.5187551e+08 | H64: =+G64/$G$74 -> 1.6863142 | AH64: Nombre de ligne Portefeuille | AI64: =COUNT(N27:N28)+COUNT(N14:N15) -> 1
AH65: Nombre de rang AIFM | AI65: =COUNTA(AF14:AF32) -> 0
B66: Disponibilité BDF | D66: =D43 -> 2114169.8 | G66: =D66+E66+F66 -> 2114169.8 | H66: =+G66/$G$74 -> 0.023474189 | AH66: Contrôle | AI66: =AI65=AI64 -> FALSE
AI67: =IF(AF67="","",#REF!)
B68: Créances BDF | D68: =D45 -> 0 | G68: =D68+E68+F68 -> 0 | H68: =+G68/$G$74 -> 0 | AH68: =SUM(AL14:AL15) -> 0 | AI68: Total
AH69: =N34 -> 1.5187551e+08 | AI69: Inventaire
B70: Dettes BDF | D70: =D47 -> -63484.78 | G70: =D70+E70+F70 -> -63484.78 | H70: =+G70/$G$74 -> -0.0007048884 | AH70: =AH68-AH69 -> -1.5187551e+08
AH71: =IF(ABS(AH70)<1,"OK","Anomalie") -> Anomalie
B72: Dettes financières BDF | D72: =D49 -> -63862605 | G72: =D72+E72+F72 -> -63862605 | H72: =+G72/$G$74 -> -0.70908348
B74: Actif net BDF | D74: =ROUND(SUM(D64:D73),2) -> 90063591 | E74: =ROUNDDOWN(SUM(E63:E73),2) -> 0 | F74: =SUM(F63:F73) -> 0 | G74: =ROUND(SUM(G64:G73),2) -> 90063591 | H74: =SUM(H63:H73) -> 1
E82: Contrôle: | F82: =IF((D51-G74)=0,"OK","Anomalies") -> OK

Sheet Calcul VL
B1: =Sommaire!A1 -> BOLZEN - SLP | D1: Calcul des valeurs liquidatives : | F1: =Sommaire!C1 -> 46022
B4: Actif net | F4: =Inventaire!C7 -> 90063591
D6: Au prorata des parts pour le 30/09/25 | G6: =IF(G7=0,"OK","Anomalies") -> OK
B7: Type de parts | C7: nombre de parts | D7: Montant libéré | E7: Actif net réparti | F7: Valeur de la parts | G7: =E12-F4 -> 0 | J7: Valeur liquidative recalculée | K7: Ecart non affectable | L7: Vérification | M7: SI l'écart divisé par le nombre de parts est inférieur à 0,01= OK
A8: FR001400XME8 | B8: Parts A1 | C8: 943268.7 | D8: 88886445 | E8: =$F$4*C8/$C$12 -> 90063495 | F8: =ROUNDDOWN(E8/C8,6) -> 95.480211 | J8: =F8*C8 -> 90063495 | K8: =E8-J8 -> 0.80409248 | L8: =+K8/C8/100 -> 8.5245326e-09 | M8: =IF(L8>0.01,"'ANOMALIE","'OK") -> 'OK
A9: FR001400XMF5 | B9: Parts A2 | C9: 0 | D9: 0 | E9: =$F$4*D9/$D$12 -> 0 | F9: =IF(C9=0,0,ROUNDDOWN(E9/C9,6)) -> 0 | J9: =F9*C9 -> 0 | K9: =E9-J9 -> 0 | L9: =+K9/C9/100 -> #DIV/0! | M9: =IF(L9>0.01,"'ANOMALIE","'OK") -> #DIV/0!
A10: FR001400XMG3 | B10: Part de Commandité | C10: 1 | D10: 94.23 | E10: =$F$4*C10/$C$12 -> 95.480212 | F10: =ROUNDDOWN(E10/C10,6) -> 95.480211 | J10: =F10*C10 -> 95.480211 | K10: =E10-J10 -> 8.5245324e-07 | L10: =+K10/C10/100 -> 8.5245324e-09 | M10: =IF(L10>0.01,"'ANOMALIE","'OK") -> 'OK
B12: Total | C12: =SUM(C8:C11) -> 943269.7 | D12: =SUM(D8:D11) -> 88886539 | E12: =SUM(E8:E11) -> 90063591 | J12: =SUM(J8:J11) -> 90063590 | K12: =SUM(K8:K11) -> 0.80409333 | L12: =+K12/C12/100 -> 8.5245326e-09 | M12: =IF(L12>0.01,"'ANOMALIE","'OK") -> 'OK
B13: Article 10

Sheet O.D Rééval
A1: Date | B1: journal | C1: Compte | D1: N° Piéces | E1: Libellé | F1: Debit | G1: Credit | H1: Monnaie
A2: =Sommaire!$C$1 -> 46022 | B2: ODSITU | C2: 31800000 | E2: ="Valorisation au "&TEXT(Sommaire!$C$1,"jj/mm/aa") -> Valorisation au 31/12/25 | F2: =IF(SUMIF(Inventaire!B12:B79,"??OC*",Inventaire!M12:M79)>0,SUMIF(Inventaire!B12:B79,"??OC*",Inventaire!M12:M79),0) -> 1712219.2 | G2: =IF(SUMIF(Inventaire!B12:B79,"??OC*",Inventaire!M12:M79)<0,-SUMIF(Inventaire!B12:B79,"??OC*",Inventaire!M12:M79),0) -> 0 | H2: E | I2: Intérêts Courus sur OC
A3: =Sommaire!$C$1 -> 46022 | B3: ODSITU | C3: 70110000 | E3: ="Valorisation au "&TEXT(Sommaire!$C$1,"jj/mm/aa") -> Valorisation au 31/12/25 | G3: =IF(SUMIF(Inventaire!B12:B79,"??OC*",Inventaire!M12:M79)>0,SUMIF(Inventaire!B12:B79,"??OC*",Inventaire!M12:M79),0) -> 1712219.2 | H3: E | I3: Intérêts courus sur OC | J3: OC
A5: =Sommaire!$C$1 -> 46022 | B5: ODSITU | C5: 31800000 | E5: ="Valorisation au "&TEXT(Sommaire!$C$1,"jj/mm/aa") -> Valorisation au 31/12/25 | F5: =IF(SUMIF(Inventaire!B12:B79,"??OS*",Inventaire!M12:M79)+SUMIF(Inventaire!B12:B79,"??OR*",Inventaire!M12:M79)+SUMIF(Inventaire!B12:B79,"??CN*",Inventaire!M12:M79)>0,SUMIF(Inventaire!B12:B79,"??OS*",Inventaire!M12:M79)+SUMIF(Inventaire!B12:B79,"??OR*",Inventaire!M12:M79)+SUMIF(Inventaire!B12:B79,"??CN*",Inventaire!M12:M79),0) -> 247916.67 | G5: =IF(SUMIF(Inventaire!B12:B79,"??OS*",Inventaire!M12:M79)+SUMIF(Inventaire!B12:B79,"??OR*",Inventaire!M12:M79)+SUMIF(Inventaire!B12:B79,"??CN*",Inventaire!M12:M79)<0,-(SUMIF(Inventaire!B12:B79,"??OS*",Inventaire!M12:M79)+SUMIF(Inventaire!B12:B79,"??OR*",Inventaire!M12:M79)+SUMIF(Inventaire!B12:B79,"??CN*",Inventaire!M12:M79)),0) -> 0 | H5: E | I5: Intérêts courus sur autres obligations
A6: =Sommaire!$C$1 -> 46022 | B6: ODSITU | C6: 70120000 | E6: ="Valorisation au "&TEXT(Sommaire!$C$1,"jj/mm/aa") -> Valorisation au 31/12/25 | G6: =IF(SUMIF(Inventaire!B12:B79,"??OS*",Inventaire!M12:M79)+SUMIF(Inventaire!B12:B79,"??OR*",Inventaire!M12:M79)+SUMIF(Inventaire!B12:B79,"??CN*",Inventaire!M12:M79)>0,SUMIF(Inventaire!B12:B79,"??OS*",Inventaire!M12:M79)+SUMIF(Inventaire!B12:B79,"??OR*",Inventaire!M12:M79)+SUMIF(Inventaire!B12:B79,"??CN*",Inventaire!M12:M79),0) -> 247916.67 | H6: E | I6: Intérêts courus sur autres obligations | J6: OS/OR/CN
A8: =Sommaire!$C$1 -> 46022 | B8: ODSITU | C8: 36800000 | E8: ="Valorisation au "&TEXT(Sommaire!$C$1,"jj/mm/aa") -> Valorisation au 31/12/25 | F8: =IF(SUMIF(Inventaire!B12:B79,"??PR*",Inventaire!M12:M79)+SUMIF(Inventaire!B12:B79,"??NO*",Inventaire!M12:M79)+SUMIF(Inventaire!B12:B79,"??CC*",Inventaire!M12:M79)>0,SUMIF(Inventaire!B12:B79,"??PR*",Inventaire!M12:M79)+SUMIF(Inventaire!B12:B79,"??NO*",Inventaire!M12:M79)+SUMIF(Inventaire!B12:B79,"??CC*",Inventaire!M12:M79),0) -> 0 | G8: =IF(SUMIF(Inventaire!B12:B79,"??PR*",Inventaire!M12:M79)+SUMIF(Inventaire!B12:B79,"??NO*",Inventaire!M12:M79)+SUMIF(Inventaire!B12:B79,"??CC*",Inventaire!M12:M79)<0,-SUMIF(Inventaire!B12:B79,"??PR*",Inventaire!M12:M79)+SUMIF(Inventaire!B12:B79,"??NO*",Inventaire!M12:M79)+SUMIF(Inventaire!B12:B79,"??CC*",Inventaire!M12:M79),0) -> 0 | H8: E | I8: intérêts courus sur Prêt
A9: =Sommaire!$C$1 -> 46022 | B9: ODSITU | C9: 70760000 | E9: ="Valorisation au "&TEXT(Sommaire!$C$1,"jj/mm/aa") -> Valorisation au 31/12/25 | G9: =IF(SUMIF(Inventaire!B12:B79,"??PR*",Inventaire!M12:M79)+SUMIF(Inventaire!B12:B79,"??NO*",Inventaire!M12:M79)+SUMIF(Inventaire!B12:B79,"??CC*",Inventaire!M12:M79)>0,SUMIF(Inventaire!B12:B79,"??PR*",Inventaire!M12:M79)+SUMIF(Inventaire!B12:B79,"??NO*",Inventaire!M12:M79)+SUMIF(Inventaire!B12:B79,"??CC*",Inventaire!M12:M79),0) -> 0 | H9: E | I9: intérêts courus sur Prêt | J9: PR/CC/NO
A11: =Sommaire!$C$1 -> 46022 | B11: ODSITU | C11: 31800000 | E11: ="Valorisation au "&TEXT(Sommaire!$C$1,"jj/mm/aa") -> Valorisation au 31/12/25 | F11: =IF(SUMIF(Inventaire!B12:B79,"??AC*",Inventaire!M12:M79)+SUMIF(Inventaire!B12:B79,"??AD*",Inventaire!M12:M79)+SUMIF(Inventaire!B12:B79,"??SA*",Inventaire!M12:M79)+SUMIF(Inventaire!B12:B79,"??BS*",Inventaire!M12:M79)>0,SUMIF(Inventaire!B12:B79,"??AC*",Inventaire!M12:M79)+SUMIF(Inventaire!B12:B79,"??AD*",Inventaire!M12:M79)+SUMIF(Inventaire!B12:B79,"??SA*",Inventaire!M12:M79)+SUMIF(Inventaire!B12:B79,"??BS*",Inventaire!M12:M79),0) -> 90591.11 | G11: =IF(SUMIF(Inventaire!B12:B79,"??AC*",Inventaire!M12:M79)+SUMIF(Inventaire!B12:B79,"??AD*",Inventaire!M12:M79)+SUMIF(Inventaire!B12:B79,"??SA*",Inventaire!M12:M79)+SUMIF(Inventaire!B12:B79,"??BS*",Inventaire!M12:M79)<0,-SUMIF(Inventaire!B12:B79,"??AC*",Inventaire!M12:M79)+SUMIF(Inventaire!B12:B79,"??AD*",Inventaire!M12:M79)+SUMIF(Inventaire!B12:B79,"??SA*",Inventaire!M12:M79)+SUMIF(Inventaire!B12:B79,"??BS*",Inventaire!M12:M79),0) -> 0 | H11: E | I11: Intérêts courus sur actions
A12: =Sommaire!$C$1 -> 46022 | B12: ODSITU | C12: 70000000 | E12: ="Valorisation au "&TEXT(Sommaire!$C$1,"jj/mm/aa") -> Valorisation au 31/12/25 | F12: =IF(SUMIF(Inventaire!B12:B79,"??AC*",Inventaire!M12:M79)+SUMIF(Inventaire!B12:B79,"??AD*",Inventaire!M12:M79)+SUMIF(Inventaire!B12:B79,"??SA*",Inventaire!M12:M79)+SUMIF(Inventaire!B12:B79,"??BS*",Inventaire!M12:M79)<0,-SUMIF(Inventaire!B12:B79,"??AC*",Inventaire!M12:M79)+SUMIF(Inventaire!B12:B79,"??AD*",Inventaire!M12:M79)+SUMIF(Inventaire!B12:B79,"??SA*",Inventaire!M12:M79)+SUMIF(Inventaire!B12:B79,"??BS*",Inventaire!M12:M79),0) -> 0 | G12: =IF(SUMIF(Inventaire!B12:B79,"??AC*",Inventaire!M12:M79)+SUMIF(Inventaire!B12:B79,"??AD*",Inventaire!M12:M79)+SUMIF(Inventaire!B12:B79,"??SA*",Inventaire!M12:M79)+SUMIF(Inventaire!B12:B79,"??BS*",Inventaire!M12:M79)>0,SUMIF(Inventaire!B12:B79,"??AC*",Inventaire!M12:M79)+SUMIF(Inventaire!B12:B79,"??AD*",Inventaire!M12:M79)+SUMIF(Inventaire!B12:B79,"??SA*",Inventaire!M12:M79)+SUMIF(Inventaire!B12:B79,"??BS*",Inventaire!M12:M79),0) -> 90591.11 | H12: E | I12: Intérêts courus sur actions | J12: AC/AD/BS/SA
A14: =Sommaire!$C$1 -> 46022 | B14: ODSITU | C14: 37000000 | E14: ="Valorisation au "&TEXT(Sommaire!$C$1,"jj/mm/aa") -> Valorisation au 31/12/25 | F14: =IF(SUMIF(Inventaire!B12:B79,"??AC*",Inventaire!L12:L79)+SUMIF(Inventaire!B12:B79,"??AD*",Inventaire!L12:L79)+SUMIF(Inventaire!B12:B79,"??SA*",Inventaire!L12:L79)+SUMIF(Inventaire!B12:B79,"??BS*",Inventaire!L12:L79)>0,(SUMIF(Inventaire!B12:B79,"??AC*",Inventaire!L12:L79)+SUMIF(Inventaire!B12:B79,"??AD*",Inventaire!L12:L79)+SUMIF(Inventaire!B12:B79,"??SA*",Inventaire!L12:L79)+SUMIF(Inventaire!B12:B79,"??BS*",Inventaire!L12:L79)),0) -> 67943.33 | G14: =IF(SUMIF(Inventaire!B12:B79,"??AC*",Inventaire!L12:L79)+SUMIF(Inventaire!B12:B79,"??AD*",Inventaire!L12:L79)+SUMIF(Inventaire!B12:B79,"??SA*",Inventaire!L12:L79)+SUMIF(Inventaire!B12:B79,"??BS*",Inventaire!L12:L79)<0,-(SUMIF(Inventaire!B12:B79,"??AC*",Inventaire!L12:L79)+SUMIF(Inventaire!B12:B79,"??AD*",Inventaire!L12:L79)+SUMIF(Inventaire!B12:B79,"??SA*",Inventaire!L12:L79)+SUMIF(Inventaire!B12:B79,"??BS*",Inventaire!L12:L79)),0) -> 0 | H14: E | I14: PVMV latentes nettes s/actions
A15: =Sommaire!$C$1 -> 46022 | B15: ODSITU | C15: 75500000 | E15: ="Valorisation au "&TEXT(Sommaire!$C$1,"jj/mm/aa") -> Valorisation au 31/12/25 | F15: =IF(SUMIF(Inventaire!B12:B79,"??AC*",Inventaire!L12:L79)+SUMIF(Inventaire!B12:B79,"??AD*",Inventaire!L12:L79)+SUMIF(Inventaire!B12:B79,"??SA*",Inventaire!L12:L79)+SUMIF(Inventaire!B12:B79,"??BS*",Inventaire!L12:L79)<0,-(SUMIF(Inventaire!B12:B79,"??AC*",Inventaire!L12:L79)+SUMIF(Inventaire!B12:B79,"??AD*",Inventaire!L12:L79)+SUMIF(Inventaire!B12:B79,"??SA*",Inventaire!L12:L79)+SUMIF(Inventaire!B12:B79,"??BS*",Inventaire!L12:L79)),0) -> 0 | G15: =IF(SUMIF(Inventaire!B12:B79,"??AC*",Inventaire!L12:L79)+SUMIF(Inventaire!B12:B79,"??AD*",Inventaire!L12:L79)+SUMIF(Inventaire!B12:B79,"??SA*",Inventaire!L12:L79)+SUMIF(Inventaire!B12:B79,"??BS*",Inventaire!L12:L79)>0,(SUMIF(Inventaire!B12:B79,"??AC*",Inventaire!L12:L79)+SUMIF(Inventaire!B12:B79,"??AD*",Inventaire!L12:L79)+SUMIF(Inventaire!B12:B79,"??SA*",Inventaire!L12:L79)+SUMIF(Inventaire!B12:B79,"??BS*",Inventaire!L12:L79)),0) -> 67943.33 | H15: E | I15: PVMV latentes nettes s/actions
A17: =Sommaire!$C$1 -> 46022 | B17: ODSITU | C17: 37100000 | E17: ="Valorisation au "&TEXT(Sommaire!$C$1,"jj/mm/aa") -> Valorisation au 31/12/25 | F17: =IF(SUMIF(Inventaire!B12:B79,"??OC*",Inventaire!L12:L79)>0,(SUMIF(Inventaire!B12:B79,"??OC*",Inventaire!L12:L79)),0) -> 226840.18 | G17: =IF(SUMIF(Inventaire!B12:B79,"??OC*",Inventaire!L12:L79)<0,-(SUMIF(Inventaire!B12:B79,"??OC*",Inventaire!L12:L79)),0) -> 0 | H17: E | I17: PVMV latentes nettes s/obligations convertibles en actions
A18: =Sommaire!$C$1 -> 46022 | B18: ODSITU | C18: 75512000 | E18: ="Valorisation au "&TEXT(Sommaire!$C$1,"jj/mm/aa") -> Valorisation au 31/12/25 | F18: =IF(SUMIF(Inventaire!B12:B79,"??OC*",Inventaire!L12:L79)<0,-(SUMIF(Inventaire!B12:B79,"??OC*",Inventaire!L12:L79)),0) -> 0 | G18: =IF(SUMIF(Inventaire!B12:B79,"??OC*",Inventaire!L12:L79)>0,(SUMIF(Inventaire!B12:B79,"??OC*",Inventaire!L12:L79)),0) -> 226840.18 | H18: E | I18: PVMV latentes nettes s/obligations convertibles en actions
A20: =Sommaire!$C$1 -> 46022 | B20: ODSITU | C20: 37100000 | E20: ="Valorisation au "&TEXT(Sommaire!$C$1,"jj/mm/aa") -> Valorisation au 31/12/25 | F20: =IF(SUMIF(Inventaire!B12:B79,"??OS*",Inventaire!L12:L79)+SUMIF(Inventaire!B12:B79,"??OR*",Inventaire!L12:L79)+SUMIF(Inventaire!B12:B79,"??CN*",Inventaire!L12:L79)>0,+(SUMIF(Inventaire!B12:B79,"??OS*",Inventaire!L12:L79)+SUMIF(Inventaire!B12:B79,"??OR*",Inventaire!L12:L79)+SUMIF(Inventaire!B12:B79,"??CN*",Inventaire!L12:L79)),0) -> 0 | G20: =IF(SUMIF(Inventaire!B12:B79,"??OS*",Inventaire!L12:L79)+SUMIF(Inventaire!B12:B79,"??OR*",Inventaire!L12:L79)+SUMIF(Inventaire!B12:B79,"??CN*",Inventaire!L12:L79)<0,-(SUMIF(Inventaire!B12:B79,"??OS*",Inventaire!L12:L79)+SUMIF(Inventaire!B12:B79,"??OR*",Inventaire!L12:L79)+SUMIF(Inventaire!B12:B79,"??CN*",Inventaire!L12:L79)),0) -> 0 | H20: E | I20: PVMV latentes nettes s/autres obligations
A21: =Sommaire!$C$1 -> 46022 | B21: ODSITU | C21: 75515000 | E21: ="Valorisation au "&TEXT(Sommaire!$C$1,"jj/mm/aa") -> Valorisation au 31/12/25 | F21: =IF(SUMIF(Inventaire!B12:B79,"??OS*",Inventaire!L12:L79)+SUMIF(Inventaire!B12:B79,"??OR*",Inventaire!L12:L79)+SUMIF(Inventaire!B12:B79,"??CN*",Inventaire!L12:L79)<0,-(SUMIF(Inventaire!B12:B79,"??OS*",Inventaire!L12:L79)+SUMIF(Inventaire!B12:B79,"??OR*",Inventaire!L12:L79)+SUMIF(Inventaire!B12:B79,"??CN*",Inventaire!L12:L79)),0) -> 0 | G21: =IF(SUMIF(Inventaire!B12:B79,"??OS*",Inventaire!L12:L79)+SUMIF(Inventaire!B12:B79,"??OR*",Inventaire!L12:L79)+SUMIF(Inventaire!B12:B79,"??CN*",Inventaire!L12:L79)>0,+(SUMIF(Inventaire!B12:B79,"??OS*",Inventaire!L12:L79)+SUMIF(Inventaire!B12:B79,"??OR*",Inventaire!L12:L79)+SUMIF(Inventaire!B12:B79,"??CN*",Inventaire!L12:L79)),0) -> 0 | H21: E | I21: PVMV latentes nettes s/autres obligations
A23: =Sommaire!$C$1 -> 46022 | B23: ODSITU | C23: 37600000 | E23: ="Valorisation au "&TEXT(Sommaire!$C$1,"jj/mm/aa") -> Valorisation au 31/12/25 | F23: =IF(SUMIF(Inventaire!B12:B79,"??PR*",Inventaire!L12:L79)+SUMIF(Inventaire!B12:B79,"??NO*",Inventaire!L12:L79)+SUMIF(Inventaire!B12:B79,"??CC*",Inventaire!L12:L79)+SUMIF(Inventaire!B12:B79,"??CT*",Inventaire!L12:L79)>0,+(SUMIF(Inventaire!B12:B79,"??PR*",Inventaire!L12:L79)+SUMIF(Inventaire!B12:B79,"??NO*",Inventaire!L12:L79)+SUMIF(Inventaire!B12:B79,"??CT*",Inventaire!L12:L79)+SUMIF(Inventaire!B12:B79,"??CC*",Inventaire!L12:L79)),0) -> 0 | G23: =IF(SUMIF(Inventaire!B12:B79,"??PR*",Inventaire!L12:L79)+SUMIF(Inventaire!B12:B79,"??NO*",Inventaire!L12:L79)+SUMIF(Inventaire!B12:B79,"??CC*",Inventaire!L12:L79)+SUMIF(Inventaire!B12:B79,"??CT*",Inventaire!L12:L79)<0,-(SUMIF(Inventaire!B12:B79,"??PR*",Inventaire!L12:L79)+SUMIF(Inventaire!B12:B79,"??NO*",Inventaire!L12:L79)+SUMIF(Inventaire!B12:B79,"??CT*",Inventaire!L12:L79)+SUMIF(Inventaire!B12:B79,"??CC*",Inventaire!L12:L79)),0) -> 0 | H23: E | I23: PVMV latentes nettes s/dépôt et autres investissements financiers
A24: =Sommaire!$C$1 -> 46022 | B24: ODSITU | C24: 75560000 | E24: ="Valorisation au "&TEXT(Sommaire!$C$1,"jj/mm/aa") -> Valorisation au 31/12/25 | F24: =IF(SUMIF(Inventaire!B12:B79,"??PR*",Inventaire!L12:L79)+SUMIF(Inventaire!B12:B79,"??NO*",Inventaire!L12:L79)+SUMIF(Inventaire!B12:B79,"??CC*",Inventaire!L12:L79)+SUMIF(Inventaire!B12:B79,"??CT*",Inventaire!L12:L79)<0,-(SUMIF(Inventaire!B12:B79,"??PR*",Inventaire!L12:L79)+SUMIF(Inventaire!B12:B79,"??NO*",Inventaire!L12:L79)+SUMIF(Inventaire!B12:B79,"??CT*",Inventaire!L12:L79)+SUMIF(Inventaire!B12:B79,"??CC*",Inventaire!L12:L79)),0) -> 0 | G24: =IF(SUMIF(Inventaire!B12:B79,"??PR*",Inventaire!L12:L79)+SUMIF(Inventaire!B12:B79,"??NO*",Inventaire!L12:L79)+SUMIF(Inventaire!B12:B79,"??CC*",Inventaire!L12:L79)+SUMIF(Inventaire!B12:B79,"??CT*",Inventaire!L12:L79)>0,+(SUMIF(Inventaire!B12:B79,"??PR*",Inventaire!L12:L79)+SUMIF(Inventaire!B12:B79,"??NO*",Inventaire!L12:L79)+SUMIF(Inventaire!B12:B79,"??CT*",Inventaire!L12:L79)+SUMIF(Inventaire!B12:B79,"??CC*",Inventaire!L12:L79)),0) -> 0 | H24: E | I24: PVMV latentes nettes s/dépôt et autres investissements financiers | J24: PR
A26: =Sommaire!$C$1 -> 46022 | B26: ODSITU | C26: 37300000 | E26: ="Valorisation au "&TEXT(Sommaire!$C$1,"jj/mm/aa") -> Valorisation au 31/12/25 | F26: =IF(SUMIF(Inventaire!C12:C79,"*sicav*",Inventaire!L12:L79)+SUMIF(Inventaire!C12:C79,"*FCP*",Inventaire!L12:L79)+SUMIF(Inventaire!C12:C79,"*FPCI*",Inventaire!L12:L79)+SUMIF(Inventaire!C12:C79,"*SLP*",Inventaire!L12:L79)+SUMIF(Inventaire!C12:C79,"*FIPS*",Inventaire!L12:L79)>0,(SUMIF(Inventaire!C12:C79,"*sicav*",Inventaire!L12:L79)+SUMIF(Inventaire!C12:C79,"*FCP*",Inventaire!L12:L79)+SUMIF(Inventaire!C12:C79,"*FPCI*",Inventaire!L12:L79)+SUMIF(Inventaire!C12:C79,"*SLP*",Inventaire!L12:L79)+SUMIF(Inventaire!C12:C79,"*FIPS*",Inventaire!L12:L79)),0) -> 0 | G26: =IF(SUMIF(Inventaire!C12:C79,"*sicav*",Inventaire!L12:L79)+SUMIF(Inventaire!C12:C79,"*FCP*",Inventaire!L12:L79)+SUMIF(Inventaire!C12:C79,"*FPCI*",Inventaire!L12:L79)+SUMIF(Inventaire!C12:C79,"*SLP*",Inventaire!L12:L79)+SUMIF(Inventaire!C12:C79,"*FIPS*",Inventaire!L12:L79)<0,-(SUMIF(Inventaire!C12:C79,"*sicav*",Inventaire!L12:L79)+SUMIF(Inventaire!C12:C79,"*FCP*",Inventaire!L12:L79)+SUMIF(Inventaire!C12:C79,"*FPCI*",Inventaire!L12:L79)+SUMIF(Inventaire!C12:C79,"*SLP*",Inventaire!L12:L79)+SUMIF(Inventaire!C12:C79,"*FIPS*",Inventaire!L12:L79)),0) -> 0 | H26: E | I26: PVMV latentes nettes s/OPC
A27: =Sommaire!$C$1 -> 46022 | B27: ODSITU | C27: 75530000 | E27: ="Valorisation au "&TEXT(Sommaire!$C$1,"jj/mm/aa") -> Valorisation au 31/12/25 | F27: =IF(SUMIF(Inventaire!C12:C79,"*sicav*",Inventaire!L12:L79)+SUMIF(Inventaire!C12:C79,"*FCP*",Inventaire!L12:L79)+SUMIF(Inventaire!C12:C79,"*FPCI*",Inventaire!L12:L79)+SUMIF(Inventaire!C12:C79,"*SLP*",Inventaire!L12:L79)+SUMIF(Inventaire!C12:C79,"*FIPS*",Inventaire!L12:L79)<0,-(SUMIF(Inventaire!C12:C79,"*sicav*",Inventaire!L12:L79)+SUMIF(Inventaire!C12:C79,"*FCP*",Inventaire!L12:L79)+SUMIF(Inventaire!C12:C79,"*FPCI*",Inventaire!L12:L79)+SUMIF(Inventaire!C12:C79,"*SLP*",Inventaire!L12:L79)+SUMIF(Inventaire!C12:C79,"*FIPS*",Inventaire!L12:L79)),0) -> 0 | G27: =IF(SUMIF(Inventaire!C12:C79,"*sicav*",Inventaire!L12:L79)+SUMIF(Inventaire!C12:C79,"*FCP*",Inventaire!L12:L79)+SUMIF(Inventaire!C12:C79,"*FPCI*",Inventaire!L12:L79)+SUMIF(Inventaire!C12:C79,"*SLP*",Inventaire!L12:L79)+SUMIF(Inventaire!C12:C79,"*FIPS*",Inventaire!L12:L79)>0,(SUMIF(Inventaire!C12:C79,"*sicav*",Inventaire!L12:L79)+SUMIF(Inventaire!C12:C79,"*FCP*",Inventaire!L12:L79)+SUMIF(Inventaire!C12:C79,"*FPCI*",Inventaire!L12:L79)+SUMIF(Inventaire!C12:C79,"*SLP*",Inventaire!L12:L79)+SUMIF(Inventaire!C12:C79,"*FIPS*",Inventaire!L12:L79)),0) -> 0 | H27: E | I27: PVMV latentes nettes s/OPC | J27: Sicav/FCP/FPCI/SLP/FIPS
A30: =Sommaire!$C$1 -> 46022 | B30: ODSITU | C30: 10410000 | E30: ="Valorisation au "&TEXT(Sommaire!$C$1,"jj/mm/aa") -> Valorisation au 31/12/25 | F30: =+'Créances_&_dettes'!G105 -> 0 | G30: 0 | H30: E | I30: Fund reserve
A31: =Sommaire!$C$1 -> 46022 | B31: ODSITU | C31: 48700000 | E31: ="Valorisation au "&TEXT(Sommaire!$C$1,"jj/mm/aa") -> Valorisation au 31/12/25 | F31: 0 | G31: =F30 -> 0 | H31: E | I31: =+I30 -> Fund reserve
A33: =Sommaire!$C$1 -> 46022 | B33: ODSITU | C33: 39800000 | E33: ="Valorisation au "&TEXT(Sommaire!$C$1,"jj/mm/aa") -> Valorisation au 31/12/25 | G33: =Emprunt!K186 -> 112604.67 | H33: E | I33: Intérêts sur emprunts
A34: =Sommaire!$C$1 -> 46022 | B34: ODSITU | C34: 60500000 | E34: ="Valorisation au "&TEXT(Sommaire!$C$1,"jj/mm/aa") -> Valorisation au 31/12/25 | F34: =G33 -> 112604.67 | H34: E | I34: Intérêts sur emprunts
E36: Contrôle | F36: =SUM(F2:F35) -> 2458115.1 | G36: =SUM(G3:G35) -> 2458115.1
E37: écart | G37: =F36-G36 -> 0 | H37: ce contrôle toujours à zéro
G38: =IF(G37=0,"OK","ANOMALIE") -> OK
B41: Ne pas modifier la présentation de cette OD
A42: à la clôture
A43: =A2 -> 46022 | B43: OD | C43: =C2 -> 31800000 | E43: =E2 -> Valorisation au 31/12/25 | F43: =F2 -> 1712219.2 | G43: =G2 -> 0 | H43: =H2 -> E | I43: =I2 -> Intérêts Courus sur OC
A44: =A3 -> 46022 | B44: OD | C44: =C3 -> 70110000 | E44: =E3 -> Valorisation au 31/12/25 | F44: =F3 -> 0 | G44: =G3 -> 1712219.2 | H44: =H3 -> E | I44: =I3 -> Intérêts courus sur OC
A46: =A5 -> 46022 | B46: OD | C46: =C5 -> 31800000 | E46: =E5 -> Valorisation au 31/12/25 | F46: =F5 -> 247916.67 | G46: =G5 -> 0 | H46: =H5 -> E | I46: =I5 -> Intérêts courus sur autres obligations
A47: =A6 -> 46022 | B47: OD | C47: =C6 -> 70120000 | E47: =E6 -> Valorisation au 31/12/25 | F47: =F6 -> 0 | G47: =G6 -> 247916.67 | H47: =H6 -> E | I47: =I6 -> Intérêts courus sur autres obligations
A49: =A8 -> 46022 | B49: OD | C49: =C8 -> 36800000 | E49: =E8 -> Valorisation au 31/12/25 | F49: =F8 -> 0 | G49: =G8 -> 0 | H49: =H8 -> E | I49: =I8 -> intérêts courus sur Prêt
A50: =A9 -> 46022 | B50: OD | C50: =C9 -> 70760000 | E50: =E9 -> Valorisation au 31/12/25 | F50: =F9 -> 0 | G50: =G9 -> 0 | H50: =H9 -> E | I50: =I9 -> intérêts courus sur Prêt
A52: =A11 -> 46022 | B52: OD | C52: =C11 -> 31800000 | E52: =E11 -> Valorisation au 31/12/25 | F52: =F11 -> 90591.11 | G52: =G11 -> 0 | H52: =H11 -> E | I52: =I11 -> Intérêts courus sur actions
A53: =A12 -> 46022 | B53: OD | C53: =C12 -> 70000000 | E53: =E12 -> Valorisation au 31/12/25 | F53: =F12 -> 0 | G53: =G12 -> 90591.11 | H53: =H12 -> E | I53: =I12 -> Intérêts courus sur actions
A55: =A14 -> 46022 | B55: OD | C55: =C14 -> 37000000 | E55: =E14 -> Valorisation au 31/12/25 | F55: =F14 -> 67943.33 | G55: =G14 -> 0 | H55: =H14 -> E | I55: =I14 -> PVMV latentes nettes s/actions
A56: =A15 -> 46022 | B56: OD | C56: =C15 -> 75500000 | E56: =E15 -> Valorisation au 31/12/25 | F56: =F15 -> 0 | G56: =G15 -> 67943.33 | H56: =H15 -> E | I56: =I15 -> PVMV latentes nettes s/actions
A58: =A17 -> 46022 | B58: OD | C58: =C17 -> 37100000 | E58: =E17 -> Valorisation au 31/12/25 | F58: =F17 -> 226840.18 | G58: =G17 -> 0 | H58: =H17 -> E | I58: =I17 -> PVMV latentes nettes s/obligations convertibles en actions
A59: =A18 -> 46022 | B59: OD | C59: =C18 -> 75512000 | E59: =E18 -> Valorisation au 31/12/25 | F59: =F18 -> 0 | G59: =G18 -> 226840.18 | H59: =H18 -> E | I59: =I18 -> PVMV latentes nettes s/obligations convertibles en actions
...

Sheet Rappro Titres & Parts
B1: =Inventaire!B1 -> BOLZEN - SLP | F1: Rapprochement Titres | J1: =Inventaire!H1 -> 46022
B4: Société et nature juridique | C4: Quantité | D4: Quantité | E4: Date | F4: ECART | G4: Quantité | H4: Date | I4: ECART | J4: Commentaires
B5: de l'instrument financier | C5: inventaire | D5: société | E5: attestation | G5: dépositaire | H5: relevé
B7: =Inventaire!C15 -> Inflexion BIDCO - ORADP 1 | C7: =Inventaire!D15 -> 10080000 | F7: =C7-D7 -> 10080000 | I7: =C7-G7 -> 10080000 | J7: Souscription 25/07/2025
B8: =Inventaire!C16 -> Inflexion BIDCO - OCADP 2 | C8: =Inventaire!D16 -> 40320000 | F8: =C8-D8 -> 40320000 | I8: =C8-G8 -> 40320000 | J8: Souscription 25/07/2025
B10: =Inventaire!C18 -> Koenig solutions - ADP B | C10: =Inventaire!D18 -> 87200 | F10: =C10-D10 -> 87200 | G10: 87200 | H10: 46022 | I10: =C10-G10 -> 0
B11: =Inventaire!C19 -> Koenig solutions - OC (SHL) | C11: =Inventaire!D19 -> 3200 | F11: =C11-D11 -> 3200 | I11: =C11-G11 -> 3200 | J11: Souscription 25/11/2025
B12: =Inventaire!C20 -> Koenig solutions - OC (Warehouse II - ADP A) | C12: =Inventaire!D20 -> 500 | F12: =C12-D12 -> 500 | I12: =C12-G12 -> 500 | J12: Souscription 25/11/2025
B14: =Inventaire!C22 -> SNIC Technologies Group - OBSA | C14: =Inventaire!D22 -> 63750000 | F14: =C14-D14 -> 63750000 | I14: =C14-G14 -> 63750000 | J14: Souscription 16/12/2025
F16: =C16-D16 -> 0 | I16: =C16-G16 -> 0
C17: =ROUND(SUM(C6:C16),2) -> 114240900 | D17: =SUM(D6:D7) -> 0 | F17: =SUM(F6:F16) -> 114240900 | G17: =SUM(G6:G16) -> 87200 | I17: =ROUND(SUM(I6:I16),2) -> 114153700
E19: Contrôle | F19: =C17-D17 -> 114240900 | I19: =C17-G17 -> 114153700
F20: =F17-F19 -> 0 | I20: =ROUND(I17-I19,2) -> 0
F21: =IF(F20=0,"OK","ANOMALIE") -> OK | I21: =IF(I20=0,"OK","ANOMALIE") -> OK
B22: Contrôle avec l'inventaire | C22: Nombre de ligne
B23: Rapprochement titres | C23: =COUNT(C7:C16) -> 6
B24: inventaire | C24: =COUNT(Inventaire!G12:G30) -> 6
C25: =IF(C23-C24<>0,"Rapprochement titres incomplet","OK") -> OK
F27: Rapprochement Parts
B29: Type de parts | C29: Quantité souscription / rachat | D29: Quantité dépositaire | E29: Date relevé | F29: ECART | G29: Commentaires
B31: Parts A1 | C31: =Inventaire!F8 -> 943268.7 | D31: 943268.7 | E31: 46022 | F31: =C31-D31 -> 0
B32: Parts A2 | C32: =Inventaire!G8 -> 0 | D32: 0 | E32: 46022 | F32: =C32-D32 -> 0
B33: Part commandité | C33: =Inventaire!H8 -> 1 | D33: 1 | E33: 46022 | F33: =C33-D33 -> 0
F34: =C34-D34 -> 0
C36: =SUM(C26:C35) -> 943269.7 | D36: =SUM(D26:D35) -> 943269.7 | F36: =SUM(F26:F35) -> 0

Sheet Hors bilan
B1: =Sommaire!A1 -> BOLZEN - SLP | C1: HORS BILAN au | E1: =Sommaire!C1 -> 46022
D5: Exercice | E5: Exercice
B6: Autres engagements (par nature de produit) | D6: =+E1 -> 46022
B8: Garanties reçues | D8: =E34 -> 0
B9: dont instruments financiers reçus en garantie et non inscrits au bilan
B11: Garanties données | D11: =D34 -> 0
B12: dont instruments financiers donnés en garantie et maintenus dans leur poste d'origine
B14: Engagements de financement reçu mais non encore tirés | D14: =E38 -> 0
B16: Engagements de financement donnés mais non encore tirés | D16: =D38 -> 0
B18: Autres engagements hors bilan
C19: Donnés | D19: =D43 -> 0 | E19: 0
C20: reçus | D20: =E43 -> 8.5438316e+08
B25: =+B1 -> BOLZEN - SLP | C25: DETAIL DES ENGAGEMENTS HORS-BILAN au | E25: =+E1 -> 46022
D28: Engagements hors bilan
D29: Engagements donnés | E29: Engagements reçus
B30: Garanties
B34: Sous-total | D34: =SUM(D30:D33) -> 0 | E34: =SUM(E30:E33) -> 0
B35: Engagements de financement mais non encore tirés
B38: Sous-total | D38: =SUM(D35:D37) -> 0 | E38: =SUM(E35:E37) -> 0
B39: Autres engagements hors bilan
B40: Engagement reçus non libérés | C40: Parts A1 | E40: 8.5438225e+08
B41: Engagement reçus non libérés | C41: Parts A2 | E41: 0 | H41: Ne jamais renseigner le non libéré des parts
B42: Engagement reçus non libérés | C42: Parts de Commandité | E42: 905.77
B43: Sous-total | D43: =SUM(D39:D42) -> 0 | E43: =SUM(E39:E42) -> 8.5438316e+08 | G43: =+IF(E43+'Capitaux propres'!D7=0,"OK","Anomalie") -> OK

Sheet PVMV
B1: =Sommaire!A1 -> BOLZEN - SLP | F1: SUIVI DES ACHATS VENTES SUR TITRES : | K1: =Sommaire!C1 -> 46022 | Q1: AIFM Turnover (T3B1) | S1: =DATE(YEAR($K$1),MONTH($K$1)-3,DAY($K$1)+1) -> 45932
Q2: Unlisted equities | R2: =+ABS(SUMIFS($J$14:$J$1057,$A$14:$A$1057,"UE",$D$14:$D$1057,">="&$S$1,$D$14:$D$1057,"<="&$K$1,$C$14:$C$1057,"<>Récap"))+ABS(SUMIFS($G$14:$G$1057,$A$14:$A$1057,"UE",$D$14:$D$1057,">="&$S$1,$D$14:$D$1057,"<="&$K$1,$C$14:$C$1057,"<>Récap")) -> 99130000
Q3: Corporate bonds not issued by financial institutions | R3: =+ABS(SUMIFS($J$14:$J$1057,$A$14:$A$1057,"OS",$D$14:$D$1057,">="&$S$1,$D$14:$D$1057,"<="&$K$1,$C$14:$C$1057,"<>Récap"))+ABS(SUMIFS($G$14:$G$1057,$A$14:$A$1057,"OS",$D$14:$D$1057,">="&$S$1,$D$14:$D$1057,"<="&$K$1,$C$14:$C$1057,"<>Récap")) -> 0
Q4: Loans | R4: =+ABS(SUMIFS($J$14:$J$1057,$A$14:$A$1057,"L",$D$14:$D$1057,">="&$S$1,$D$14:$D$1057,"<="&$K$1,$C$14:$C$1057,"<>Récap"))+ABS(SUMIFS($G$14:$G$1057,$A$14:$A$1057,"L",$D$14:$D$1057,">="&$S$1,$D$14:$D$1057,"<="&$K$1,$C$14:$C$1057,"<>Récap")) -> 0
Q5: Collective Investment Undertakings | R5: =+ABS(SUMIFS($J$14:$J$1057,$A$14:$A$1057,"CIU",$D$14:$D$1057,">="&$S$1,$D$14:$D$1057,"<="&$K$1,$C$14:$C$1057,"<>Récap"))+ABS(SUMIFS($G$14:$G$1057,$A$14:$A$1057,"CIU",$D$14:$D$1057,">="&$S$1,$D$14:$D$1057,"<="&$K$1,$C$14:$C$1057,"<>Récap")) -> 0
Q6: Convertible bonds not issued by financial institutionsNon-investment grade | R6: =+ABS(SUMIFS($J$14:$J$1057,$A$14:$A$1057,"OC",$D$14:$D$1057,">="&$S$1,$D$14:$D$1057,"<="&$K$1,$C$14:$C$1057,"<>Récap"))+ABS(SUMIFS($G$14:$G$1057,$A$14:$A$1057,"OC",$D$14:$D$1057,">="&$S$1,$D$14:$D$1057,"<="&$K$1,$C$14:$C$1057,"<>Récap")) -> 0
B10: Les instruments financiers sont comptabilisés "frais exclus"; les droits d'enregistrement
B11: sont à comptabiliser en charges | E11: ACHATS | H11: VENTES | L11: SOLDES | O11: PLUS VALUES REALISEES | P11: MOINS VALUES REALISEES | Q11: Prix de vente- prix de revient (2) | R11: Sommes des plus ou moins values (1) | S11: Contrôle (2)-(1)
B12: TITRE | C12: LIBELLE | D12: DATE OPE | E12: QTE | F12: PR UNITAIRE | G12: PR OPERATION | H12: QTE | I12: PV UNITAIRE | J12: PV OPERATION | K12: PR OPERATION | L12: QUANTITE | M12: PR CUMULE | N12: PR UNIT. MOYEN | Q12: Plus ou moins values nettes | R12: Plus ou moins values nettes | S12: Contrôle
C13: Report | N13: =+IF(L13=0,0,M13/L13) -> 0 | O13: =IF(J13-K13>0,J13-K13,0) -> 0 | P13: =IF(J13-K13<0,J13-K13,0) -> 0 | Q13: =+J13-K13 -> 0 | R13: =+O13+P13 -> 0 | S13: =+Q13-R13 -> 0
A14: UE | B14: Inflexion BIDCO - OCADP 2 | C14: Souscription | D14: 45863 | E14: 40320000 | F14: =IF(E14=0,0,G14/E14) -> 1 | G14: 40320000 | I14: =IF(H14=0,0,J14/H14) -> 0 | K14: =+H14*N13 -> 0 | L14: =+L13+E14-H14 -> 40320000 | M14: =+M13+G14-K14 -> 40320000 | N14: =+ROUND(IF(L14=0,0,M14/L14),2) -> 1 | O14: =IF(J14-K14>0,J14-K14,0) -> 0 | P14: =IF(J14-K14<0,J14-K14,0) -> 0 | Q14: =+J14-K14 -> 0 | R14: =+O14+P14 -> 0 | S14: =+Q14-R14 -> 0
A15: UE | B15: Inflexion BIDCO - OCADP 2 | F15: =IF(E15=0,0,G15/E15) -> 0 | I15: =IF(H15=0,0,J15/H15) -> 0 | K15: =+H15*N14 -> 0 | L15: =+L14+E15-H15 -> 40320000 | M15: =+M14+G15-K15 -> 40320000 | N15: =+ROUND(IF(L15=0,0,M15/L15),2) -> 1 | O15: =IF(J15-K15>0,J15-K15,0) -> 0 | P15: =IF(J15-K15<0,J15-K15,0) -> 0 | Q15: =+J15-K15 -> 0 | R15: =+O15+P15 -> 0 | S15: =+Q15-R15 -> 0
A16: UE | B16: Inflexion BIDCO - OCADP 2 | F16: =IF(E16=0,0,G16/E16) -> 0 | I16: =IF(H16=0,0,J16/H16) -> 0 | K16: =+H16*N15 -> 0 | L16: =+L15+E16-H16 -> 40320000 | M16: =+M15+G16-K16 -> 40320000 | N16: =+ROUND(IF(L16=0,0,M16/L16),2) -> 1 | O16: =IF(J16-K16>0,J16-K16,0) -> 0 | P16: =IF(J16-K16<0,J16-K16,0) -> 0 | Q16: =+J16-K16 -> 0 | R16: =+O16+P16 -> 0 | S16: =+Q16-R16 -> 0
A17: UE | B17: Inflexion BIDCO - OCADP 2 | F17: =IF(E17=0,0,G17/E17) -> 0 | I17: =IF(H17=0,0,J17/H17) -> 0 | K17: =+H17*N16 -> 0 | L17: =+L16+E17-H17 -> 40320000 | M17: =+M16+G17-K17 -> 40320000 | N17: =+ROUND(IF(L17=0,0,M17/L17),2) -> 1 | O17: =IF(J17-K17>0,J17-K17,0) -> 0 | P17: =IF(J17-K17<0,J17-K17,0) -> 0 | Q17: =+J17-K17 -> 0 | R17: =+O17+P17 -> 0 | S17: =+Q17-R17 -> 0
A18: UE | B18: Inflexion BIDCO - OCADP 2 | F18: =IF(E18=0,0,G18/E18) -> 0 | I18: =IF(H18=0,0,J18/H18) -> 0 | K18: =+H18*N17 -> 0 | L18: =+L17+E18-H18 -> 40320000 | M18: =+M17+G18-K18 -> 40320000 | N18: =+ROUND(IF(L18=0,0,M18/L18),2) -> 1 | O18: =IF(J18-K18>0,J18-K18,0) -> 0 | P18: =IF(J18-K18<0,J18-K18,0) -> 0 | Q18: =+J18-K18 -> 0 | R18: =+O18+P18 -> 0 | S18: =+Q18-R18 -> 0
A19: UE | B19: Inflexion BIDCO - OCADP 2 | F19: =IF(E19=0,0,G19/E19) -> 0 | I19: =IF(H19=0,0,J19/H19) -> 0 | K19: =+H19*N18 -> 0 | L19: =+L18+E19-H19 -> 40320000 | M19: =+M18+G19-K19 -> 40320000 | N19: =+ROUND(IF(L19=0,0,M19/L19),2) -> 1 | O19: =IF(J19-K19>0,J19-K19,0) -> 0 | P19: =IF(J19-K19<0,J19-K19,0) -> 0 | Q19: =+J19-K19 -> 0 | R19: =+O19+P19 -> 0 | S19: =+Q19-R19 -> 0
A20: UE | B20: =B19 -> Inflexion BIDCO - OCADP 2 | C20: Récap | D20: =+$K$1 -> 46022 | E20: =SUM(E14:E19) -> 40320000 | F20: =+IF(E20=0,0,G20/E20) -> 1 | G20: =SUM(G13:G19) -> 40320000 | H20: =SUM(H13:H19) -> 0 | I20: =+IF(H20=0,0,J20/H20) -> 0 | J20: =SUM(J13:J19) -> 0 | K20: =SUM(K13:K19) -> 0 | L20: =+L19 -> 40320000 | M20: =+M19 -> 40320000 | N20: =+IF(L20=0,0,M20/L20) -> 1 | O20: =SUM(O13:O16) -> 0 | P20: =SUM(P13:P16) -> 0 | Q20: =+J20-K20 -> 0 | R20: =+O20+P20 -> 0 | S20: =+Q20-R20 -> 0
A21: UE | C21: Report | Q21: =+J21-K21 -> 0 | R21: =+O21+P21 -> 0 | S21: =+Q21-R21 -> 0
A22: UE | B22: Inflexion BIDCO - ORADP 1 | C22: Souscription | D22: 45863 | E22: 10080000 | F22: =IF(E22=0,0,G22/E22) -> 1 | G22: 10080000 | I22: =IF(H22=0,0,J22/H22) -> 0 | K22: =+H22*N21 -> 0 | L22: =+L21+E22-H22 -> 10080000 | M22: =+M21+G22-K22 -> 10080000 | N22: =+IF(L22=0,0,M22/L22) -> 1 | O22: =IF(J22-K22>0,J22-K22,0) -> 0 | P22: =IF(J22-K22<0,J22-K22,0) -> 0 | Q22: =+J22-K22 -> 0 | R22: =+O22+P22 -> 0 | S22: =+Q22-R22 -> 0
A23: UE | B23: =B22 -> Inflexion BIDCO - ORADP 1 | F23: =IF(E23=0,0,G23/E23) -> 0 | I23: =IF(H23=0,0,J23/H23) -> 0 | K23: =+H23*N22 -> 0 | L23: =+L22+E23-H23 -> 10080000 | M23: =+M22+G23-K23 -> 10080000 | N23: =+IF(L23=0,0,M23/L23) -> 1 | O23: =IF(J23-K23>0,J23-K23,0) -> 0 | P23: =IF(J23-K23<0,J23-K23,0) -> 0 | Q23: =+J23-K23 -> 0 | R23: =+O23+P23 -> 0 | S23: =+Q23-R23 -> 0
A24: UE | B24: =B23 -> Inflexion BIDCO - ORADP 1 | F24: =IF(E24=0,0,G24/E24) -> 0 | I24: =IF(H24=0,0,J24/H24) -> 0 | K24: =+H24*N23 -> 0 | L24: =+L23+E24-H24 -> 10080000 | M24: =+M23+G24-K24 -> 10080000 | N24: =+IF(L24=0,0,M24/L24) -> 1 | O24: =IF(J24-K24>0,J24-K24,0) -> 0 | P24: =IF(J24-K24<0,J24-K24,0) -> 0 | Q24: =+J24-K24 -> 0 | R24: =+O24+P24 -> 0 | S24: =+Q24-R24 -> 0
A25: UE | B25: =B24 -> Inflexion BIDCO - ORADP 1 | F25: =IF(E25=0,0,G25/E25) -> 0 | I25: =IF(H25=0,0,J25/H25) -> 0 | K25: =+H25*N24 -> 0 | L25: =+L24+E25-H25 -> 10080000 | M25: =+M24+G25-K25 -> 10080000 | N25: =+IF(L25=0,0,M25/L25) -> 1 | O25: =IF(J25-K25>0,J25-K25,0) -> 0 | P25: =IF(J25-K25<0,J25-K25,0) -> 0 | Q25: =+J25-K25 -> 0 | R25: =+O25+P25 -> 0 | S25: =+Q25-R25 -> 0
A26: UE | B26: =B25 -> Inflexion BIDCO - ORADP 1 | F26: =IF(E26=0,0,G26/E26) -> 0 | I26: =IF(H26=0,0,J26/H26) -> 0 | K26: =+H26*N25 -> 0 | L26: =+L25+E26-H26 -> 10080000 | M26: =+M25+G26-K26 -> 10080000 | N26: =+IF(L26=0,0,M26/L26) -> 1 | O26: =IF(J26-K26>0,J26-K26,0) -> 0 | P26: =IF(J26-K26<0,J26-K26,0) -> 0 | Q26: =+J26-K26 -> 0 | R26: =+O26+P26 -> 0 | S26: =+Q26-R26 -> 0
A27: UE | B27: =B26 -> Inflexion BIDCO - ORADP 1 | F27: =IF(E27=0,0,G27/E27) -> 0 | I27: =IF(H27=0,0,J27/H27) -> 0 | K27: =+H27*N26 -> 0 | L27: =+L26+E27-H27 -> 10080000 | M27: =+M26+G27-K27 -> 10080000 | N27: =+IF(L27=0,0,M27/L27) -> 1 | O27: =IF(J27-K27>0,J27-K27,0) -> 0 | P27: =IF(J27-K27<0,J27-K27,0) -> 0 | Q27: =+J27-K27 -> 0 | R27: =+O27+P27 -> 0 | S27: =+Q27-R27 -> 0
A28: UE | B28: =B27 -> Inflexion BIDCO - ORADP 1 | F28: =IF(E28=0,0,G28/E28) -> 0 | I28: =IF(H28=0,0,J28/H28) -> 0 | K28: =+H28*N27 -> 0 | L28: =+L27+E28-H28 -> 10080000 | M28: =+M27+G28-K28 -> 10080000 | N28: =+IF(L28=0,0,M28/L28) -> 1 | O28: =IF(J28-K28>0,J28-K28,0) -> 0 | P28: =IF(J28-K28<0,J28-K28,0) -> 0 | Q28: =+J28-K28 -> 0 | R28: =+O28+P28 -> 0 | S28: =+Q28-R28 -> 0
A29: UE | B29: =B28 -> Inflexion BIDCO - ORADP 1 | F29: =IF(E29=0,0,G29/E29) -> 0 | I29: =IF(H29=0,0,J29/H29) -> 0 | K29: =+H29*N28 -> 0 | L29: =+L28+E29-H29 -> 10080000 | M29: =+M28+G29-K29 -> 10080000 | N29: =+IF(L29=0,0,M29/L29) -> 1 | O29: =IF(J29-K29>0,J29-K29,0) -> 0 | P29: =IF(J29-K29<0,J29-K29,0) -> 0 | Q29: =+J29-K29 -> 0 | R29: =+O29+P29 -> 0 | S29: =+Q29-R29 -> 0
A30: UE | B30: =B29 -> Inflexion BIDCO - ORADP 1 | F30: =IF(E30=0,0,G30/E30) -> 0 | I30: =IF(H30=0,0,J30/H30) -> 0 | K30: =+H30*N29 -> 0 | L30: =+L29+E30-H30 -> 10080000 | M30: =+M29+G30-K30 -> 10080000 | N30: =+IF(L30=0,0,M30/L30) -> 1 | O30: =IF(J30-K30>0,J30-K30,0) -> 0 | P30: =IF(J30-K30<0,J30-K30,0) -> 0 | Q30: =+J30-K30 -> 0 | R30: =+O30+P30 -> 0 | S30: =+Q30-R30 -> 0
A31: UE | B31: =B30 -> Inflexion BIDCO - ORADP 1 | F31: =IF(E31=0,0,G31/E31) -> 0 | I31: =IF(H31=0,0,J31/H31) -> 0 | K31: =+H31*N30 -> 0 | L31: =+L30+E31-H31 -> 10080000 | M31: =+M30+G31-K31 -> 10080000 | N31: =+IF(L31=0,0,M31/L31) -> 1 | O31: =IF(J31-K31>0,J31-K31,0) -> 0 | P31: =IF(J31-K31<0,J31-K31,0) -> 0 | Q31: =+J31-K31 -> 0 | R31: =+O31+P31 -> 0 | S31: =+Q31-R31 -> 0
A32: UE | B32: =B31 -> Inflexion BIDCO - ORADP 1 | F32: =IF(E32=0,0,G32/E32) -> 0 | I32: =IF(H32=0,0,J32/H32) -> 0 | K32: =+H32*N31 -> 0 | L32: =+L31+E32-H32 -> 10080000 | M32: =+M31+G32-K32 -> 10080000 | N32: =+IF(L32=0,0,M32/L32) -> 1 | O32: =IF(J32-K32>0,J32-K32,0) -> 0 | P32: =IF(J32-K32<0,J32-K32,0) -> 0 | Q32: =+J32-K32 -> 0 | R32: =+O32+P32 -> 0 | S32: =+Q32-R32 -> 0
A33: UE | B33: =B32 -> Inflexion BIDCO - ORADP 1 | F33: =IF(E33=0,0,G33/E33) -> 0 | I33: =IF(H33=0,0,J33/H33) -> 0 | K33: =+H33*N32 -> 0 | L33: =+L32+E33-H33 -> 10080000 | M33: =+M32+G33-K33 -> 10080000 | N33: =+IF(L33=0,0,M33/L33) -> 1 | O33: =IF(J33-K33>0,J33-K33,0) -> 0 | P33: =IF(J33-K33<0,J33-K33,0) -> 0 | Q33: =+J33-K33 -> 0 | R33: =+O33+P33 -> 0 | S33: =+Q33-R33 -> 0
A34: UE | B34: =B33 -> Inflexion BIDCO - ORADP 1 | F34: =IF(E34=0,0,G34/E34) -> 0 | I34: =IF(H34=0,0,J34/H34) -> 0 | K34: =+H34*N33 -> 0 | L34: =+L33+E34-H34 -> 10080000 | M34: =+M33+G34-K34 -> 10080000 | N34: =+IF(L34=0,0,M34/L34) -> 1 | O34: =IF(J34-K34>0,J34-K34,0) -> 0 | P34: =IF(J34-K34<0,J34-K34,0) -> 0 | Q34: =+J34-K34 -> 0 | R34: =+O34+P34 -> 0 | S34: =+Q34-R34 -> 0
A35: UE | B35: =B34 -> Inflexion BIDCO - ORADP 1 | C35: Récap | D35: =+$K$1 -> 46022 | E35: =SUM(E22:E34) -> 10080000 | F35: =+IF(E35=0,0,G35/E35) -> 1 | G35: =SUM(G22:G34) -> 10080000 | H35: =SUM(H22:H34) -> 0 | I35: =+IF(H35=0,0,J35/H35) -> 0 | J35: =SUM(J22:J34) -> 0 | K35: =SUM(K21:K34) -> 0 | L35: =+L34 -> 10080000 | M35: =+M34 -> 10080000 | N35: =+IF(L35=0,0,M35/L35) -> 1 | O35: =SUM(O21:O34) -> 0 | P35: =SUM(P21:P34) -> 0 | Q35: =+J35-K35 -> 0 | R35: =+O35+P35 -> 0 | S35: =+Q35-R35 -> 0
A36: UE | C36: Report | Q36: =+J36-K36 -> 0 | R36: =+O36+P36 -> 0 | S36: =+Q36-R36 -> 0
A37: UE | B37: Koenig solutions - ADP B | C37: Souscription | D37: 45986 | E37: 87200 | F37: =IF(E37=0,0,G37/E37) -> 1 | G37: 87200 | I37: =IF(H37=0,0,J37/H37) -> 0 | K37: =+H37*N36 -> 0 | L37: =+L36+E37-H37 -> 87200 | M37: =+M36+G37-K37 -> 87200 | N37: =+IF(L37=0,0,M37/L37) -> 1 | O37: =IF(J37-K37>0,J37-K37,0) -> 0 | P37: =IF(J37-K37<0,J37-K37,0) -> 0 | Q37: =+J37-K37 -> 0 | R37: =+O37+P37 -> 0 | S37: =+Q37-R37 -> 0
A38: UE | B38: =B37 -> Koenig solutions - ADP B | C38: Prime d'émission | D38: 45986 | F38: =IF(E38=0,0,G38/E38) -> 0 | G38: 8632800 | I38: =IF(H38=0,0,J38/H38) -> 0 | K38: =+H38*N37 -> 0 | L38: =+L37+E38-H38 -> 87200 | M38: =+M37+G38-K38 -> 8720000 | N38: =+IF(L38=0,0,M38/L38) -> 100 | O38: =IF(J38-K38>0,J38-K38,0) -> 0 | P38: =IF(J38-K38<0,J38-K38,0) -> 0 | Q38: =+J38-K38 -> 0 | R38: =+O38+P38 -> 0 | S38: =+Q38-R38 -> 0
A39: UE | B39: =B38 -> Koenig solutions - ADP B | F39: =IF(E39=0,0,G39/E39) -> 0 | I39: =IF(H39=0,0,J39/H39) -> 0 | L39: =+L38+E39-H39 -> 87200 | M39: =+M38+G39-K39 -> 8720000 | N39: =+IF(L39=0,0,M39/L39) -> 100 | O39: =IF(J39-K39>0,J39-K39,0) -> 0 | P39: =IF(J39-K39<0,J39-K39,0) -> 0 | Q39: =+J39-K39 -> 0 | R39: =+O39+P39 -> 0 | S39: =+Q39-R39 -> 0
A40: UE | B40: =B39 -> Koenig solutions - ADP B | C40: Récap | D40: =+$K$1 -> 46022 | E40: =SUM(E37:E39) -> 87200 | F40: =+IF(E40=0,0,G40/E40) -> 100 | G40: =SUM(G36:G39) -> 8720000 | H40: =SUM(H36:H39) -> 0 | I40: =+IF(H40=0,0,J40/H40) -> 0 | J40: =SUM(J36:J39) -> 0 | K40: =SUM(K36:K39) -> 0 | L40: =+L39 -> 87200 | M40: =+M39 -> 8720000 | N40: =+IF(L40=0,0,M40/L40) -> 100 | O40: =SUM(O36:O39) -> 0 | P40: =SUM(P36:P39) -> 0 | Q40: =+J40-K40 -> 0 | R40: =+O40+P40 -> 0 | S40: =+Q40-R40 -> 0
A41: UE | C41: Report | Q41: =+J41-K41 -> 0 | R41: =+O41+P41 -> 0 | S41: =+Q41-R41 -> 0
A42: UE | B42: Koenig solutions - OC (SHL) | C42: Souscription | D42: 45986 | E42: 3200 | F42: =IF(E42=0,0,G42/E42) -> 1 | G42: 3200 | I42: =IF(H42=0,0,J42/H42) -> 0 | K42: =+H42*N41 -> 0 | L42: =+L41+E42-H42 -> 3200 | M42: =+M41+G42-K42 -> 3200 | N42: =+IF(L42=0,0,M42/L42) -> 1 | O42: =IF(J42-K42>0,J42-K42,0) -> 0 | P42: =IF(J42-K42<0,J42-K42,0) -> 0 | Q42: =+J42-K42 -> 0 | R42: =+O42+P42 -> 0 | S42: =+Q42-R42 -> 0
A43: UE | B43: =B42 -> Koenig solutions - OC (SHL) | C43: Prime d'émission | D43: 45986 | F43: =IF(E43=0,0,G43/E43) -> 0 | G43: 26156800 | I43: =IF(H43=0,0,J43/H43) -> 0 | K43: =+H43*N42 -> 0 | L43: =+L42+E43-H43 -> 3200 | M43: =+M42+G43-K43 -> 26160000 | N43: =+IF(L43=0,0,M43/L43) -> 8175 | O43: =IF(J43-K43>0,J43-K43,0) -> 0 | P43: =IF(J43-K43<0,J43-K43,0) -> 0 | Q43: =+J43-K43 -> 0 | R43: =+O43+P43 -> 0 | S43: =+Q43-R43 -> 0
...

Sheet Intérêts Obligations
B1: =Sommaire!A1 -> BOLZEN - SLP | F1: Intérêts courus sur obligations convertibles | I1: =+Sommaire!C1 -> 46022
B4: Inflexion BIDCO - OCADP 2 | H4: Capitalisation : 29/07
B5: Date debut période | C5: Date fin période | D5: Jours | E5: Base | F5: Mouvement | G5: Capitalisation | H5: Base de calcul | I5: Taux fixe ou marge | J5: Taux variable : Euribor X mois | K5: Dividendes / coupons | L5: Intérêts courus
B7: 45867 | C7: 45930 | D7: =+C7-B7 -> 63 | E7: 365 | F7: 40320000 | H7: =+H6+F7+G7 -> 40320000 | I7: 0.1 | K7: =ROUND((H7*D7*(I7+J7))/E7,2) -> 695934.25 | L7: =+K7 -> 695934.25
B8: =C7 -> 45930 | C8: 46022 | D8: =+C8-B8 -> 92 | E8: 365 | H8: =+H7+F8+G8 -> 40320000 | I8: 0.1 | K8: =ROUND((H8*D8*(I8+J8))/E8,2) -> 1016284.9 | L8: =+K8 -> 1016284.9
B21: Total | F21: =SUM(F6:F20) -> 40320000 | G21: =SUM(G7:G20) -> 0 | H21: =+VLOOKUP($I$1,C5:H20,6,FALSE) -> 40320000 | K21: =SUM(K6:K20) -> 1712219.2 | L21: =SUM(L6:L20) -> 1712219.2
B22: échéance 29/01/2033 | J22: Provision | K22: 0 | L22: =K22*L21 -> 0
L23: =L21-L22 -> 1712219.2
B27: Koenig - ADP B | H27: Capitalisation : 27/11
B28: Date debut période | C28: Date fin période | D28: Jours | E28: Base | F28: Mouvement | G28: Capitalisation | H28: Base de calcul | I28: Taux fixe ou marge | J28: Taux variable : Euribor X mois | K28: Dividendes / coupons | L28: Intérêts courus
B30: 45988 | C30: 46022 | D30: =+C30-B30 -> 34 | E30: 360 | F30: 8720000 | H30: =+H29+F30+G30 -> 8720000 | I30: 0.11 | K30: =ROUND((H30*D30*(I30+J30))/E30,2) -> 90591.11 | L30: =+K30 -> 90591.11
B44: Total | F44: =SUM(F29:F43) -> 8720000 | G44: =SUM(G30:G43) -> 0 | H44: =+VLOOKUP($I$1,C28:H43,6,FALSE) -> 8720000 | K44: =SUM(K29:K43) -> 90591.11 | L44: =SUM(L29:L43) -> 90591.11
J45: Provision | K45: 0 | L45: =K45*L44 -> 0
L46: =L44-L45 -> 90591.11
B52: Koenig - OC (SHL) | H52: Capitalisation : 25/11
B53: Date debut période | C53: Date fin période | D53: Jours | E53: Base | F53: Mouvement | G53: Capitalisation | H53: Base de calcul | I53: Taux fixe ou marge | J53: Taux variable : Euribor X mois | K53: Dividendes / coupons | L53: Intérêts courus
B55: 45986 | C55: 46022 | D55: =+C55-B55 -> 36 | E55: 365 | F55: 26160000 | H55: =+H54+F55+G55 -> 26160000 | I55: 0 | K55: =ROUND((H55*D55*(I55+J55))/E55,2) -> 0 | L55: =+K55 -> 0
F57: Pas de calcul d'intérêts
B60: Total | F60: =SUM(F54:F59) -> 26160000 | G60: =SUM(G55:G59) -> 0 | H60: =+VLOOKUP($I$1,C53:H59,6,FALSE) -> 26160000 | K60: =SUM(K54:K59) -> 0 | L60: =SUM(L54:L59) -> 0
J61: Provision | K61: 0 | L61: =K61*L60 -> 0
B62: Taux d'intérêts : 0% | L62: =L60-L61 -> 0
B67: Koenig - OC (Warehouse II - ADP A) | H67: Capitalisation : 25/11
B68: Date debut période | C68: Date fin période | D68: Jours | E68: Base | F68: Mouvement | G68: Capitalisation | H68: Base de calcul | I68: Taux fixe ou marge | J68: Taux variable : Euribor X mois | K68: Dividendes / coupons | L68: Intérêts courus
B70: 45986 | C70: 46022 | D70: =+C70-B70 -> 36 | E70: 365 | F70: 500000 | H70: =+H69+F70+G70 -> 500000 | K70: =ROUND((H70*D70*(I70+J70))/E70,2) -> 0 | L70: =+K70 -> 0
F72: Pas de calcul d'intérêts
B75: Total | F75: =SUM(F69:F74) -> 500000 | G75: =SUM(G70:G74) -> 0 | H75: =+VLOOKUP($I$1,C68:H74,6,FALSE) -> 500000 | K75: =SUM(K69:K74) -> 0 | L75: =SUM(L69:L74) -> 0
J76: Provision | K76: 0 | L76: =K76*L75 -> 0
B77: Maturité : 31/12/2038 | L77: =L75-L76 -> 0
B78: Taux d'intérêts: 0%
B81: SNIC - OBSA | H81: Capitalisation : 17/12
B82: Date debut période | C82: Date fin période | D82: Jours | E82: Base | F82: Mouvement | G82: Capitalisation | H82: Base de calcul | I82: Taux fixe ou marge | J82: Taux variable : Euribor X mois | K82: Dividendes / coupons | L82: Intérêts courus
B84: 46008 | C84: 46022 | D84: =+C84-B84 -> 14 | E84: 360 | F84: 63750000 | H84: =+H83+F84+G84 -> 63750000 | I84: 0.1 | K84: =ROUND((H84*D84*(I84+J84))/E84,2) -> 247916.67 | L84: =+K84 -> 247916.67
B98: Total | F98: =SUM(F83:F97) -> 63750000 | G98: =SUM(G84:G97) -> 0 | H98: =+VLOOKUP($I$1,C82:H97,6,FALSE) -> 63750000 | K98: =SUM(K83:K97) -> 247916.67 | L98: =SUM(L83:L97) -> 247916.67
J99: Provision | K99: 0 | L99: =K99*L98 -> 0
B100: Date de maturité: 16/12/2033 | L100: =L98-L99 -> 247916.67
G104: Récap intérêt Obligations | H104: Inventaire | I104: Ecart | J104: Contrôle
F105: Intérêts Capitalisés | G105: =G21+G44+G60+G75 -> 0 | H105: =ROUND(SUMIF(Inventaire!B15:B83,"??OS*",Inventaire!I15:I83)+SUMIF(Inventaire!B15:B83,"??OR*",Inventaire!I15:I83)+SUMIF(Inventaire!B15:B83,"??CN*",Inventaire!I15:I83)+SUMIF(Inventaire!B12:B79,"??OC*",Inventaire!I12:I79),2) -> 0 | I105: =G105-H105 -> 0 | J105: =IF(ROUND(I105,2)=0,"OK","ANOMALIE") -> OK
F106: Intérêts Courus | G106: =L23+L46+L62+L77+L100 -> 2050727 | H106: =SUMIF(Inventaire!B15:B83,"??OS*",Inventaire!M15:M83)+SUMIF(Inventaire!B15:B83,"??OR*",Inventaire!M15:M83)+SUMIF(Inventaire!B15:B83,"??CN*",Inventaire!M15:M83)+SUMIF(Inventaire!B12:B79,"??OC*",Inventaire!M12:M79)+SUMIF(Inventaire!B15:B83,"??AD*",Inventaire!M15:M83) -> 2050727 | I106: =G106-H106 -> 0 | J106: =IF(ROUND(I106,2)=0,"OK","ANOMALIE") -> OK

Sheet Emprunt
B1: =Sommaire!A1 -> BOLZEN - SLP | G1: COMPTE COURANT AU | I1: =Sommaire!C1 -> 46022
B3: Emprunt - Facility agrement loan n°1
B4: Date de début de période | C4: Date de fin de période | D4: Durée | E4: Base | F4: Intitulé | G4: Mouvements | H4: Solde progressif | I4: marge | J4: Taux Euribor | K4: Intérêts | L4: Intérêt payé | M4: Intérêts courus
B6: 45862 | C6: 45930 | D6: =C6-B6 -> 68 | E6: 360 | F6: Tirage | G6: 50400000 | H6: =H5+G6 -> 50400000 | I6: 0.018 | J6: 0.02032 | K6: =ROUND((D6*(I6+J6)*H6)/E6,2) -> 364806.4 | M6: =K6+L6 -> 364806.4
B7: =C6 -> 45930 | C7: 46020 | D7: =C7-B7 -> 90 | E7: 360 | H7: =H6+G7 -> 50400000 | I7: 0.018 | J7: 0.02032 | K7: =ROUND((D7*(I7+J7)*H7)/E7,2) -> 482832 | M7: =K7+L7 -> 482832
F9: Remboursements | G9: -50400000 | K9: -847638.4 | M9: -847638.4
G16: =SUM(G5:G15) -> 0 | K16: =SUM(K6:K15) -> 0 | M16: =SUM(M6:M15) -> 0
B18: Maturité | D18: 46048
B19: intérêt au 26/01/2026 : | D19: 997852.8
B20: Mage: | D20: 0.018
B21: Montant emprunté | D21: =G16 -> 0
B22: Emprunt - Commiment fee loan n°1
B23: Date de début de période | C23: Date de fin de période | D23: Durée | E23: Base | F23: Intitulé | G23: Mouvements | H23: Solde progressif | I23: Taux appliqué | J23: Intérêts | K23: Intérêts courus
B25: 45862 | C25: 45930 | D25: =C25-B25 -> 68 | E25: 360 | F25: Commission de non utilisation | G25: =D21-G16 -> 0 | H25: =G25+H24 -> 0 | I25: 0.003 | J25: =ROUND((D25*(I25)*H25)/E25,2) -> 0
B26: =C25 -> 45930 | C26: 46020 | D26: =C26-B26 -> 90 | E26: 360 | H26: =G26+H25 -> 0 | I26: 0.003 | J26: =ROUND((D26*(I26)*H26)/E26,2) -> 0
G43: =G29 -> 0 | H43: =+H29 -> 0 | J43: =SUM(J25:J42) -> 0 | K43: =SUM(K25:K32) -> 0
B52: Emprunt - Facility agrement loan n°3
B53: Date de début de période | C53: Date de fin de période | D53: Durée | E53: Base | F53: Intitulé | G53: Mouvements | H53: Solde progressif | I53: marge | J53: Taux Euribor | K53: Intérêts | L53: Intérêt payé | M53: Intérêts courus
B55: 45982 | C55: 46020 | D55: =C55-B55 -> 38 | E55: 360 | F55: Tirage | G55: 35380000 | H55: =H54+G55 -> 35380000 | I55: 0.018 | J55: 0.021 | K55: =ROUND((D55*(I55+J55)*H55)/E55,2) -> 145647.67 | M55: =K55+L55 -> 145647.67
F57: Remboursement | G57: -35380000 | K57: -145647.67 | M57: -145647.67
G65: =SUM(G54:G64) -> 0 | K65: =SUM(K55:K64) -> 0 | M65: =SUM(M55:M64) -> 0
B67: Maturité | D67: 46346
B68: intérêt au 30/03/2026 : | D68: 494435.5
B69: Mage: | D69: 0.018
B70: Montant emprunté | D70: =G65 -> 0
B71: Emprunt - Commiment fee loan n°3
B72: Date de début de période | C72: Date de fin de période | D72: Durée | E72: Base | F72: Intitulé | G72: Mouvements | H72: Solde progressif | I72: Taux appliqué | J72: Intérêts | K72: Intérêts courus
B74: 45982 | C74: 46020 | D74: =C74-B74 -> 38 | E74: 360 | F74: Commission de non utilisation | G74: =D70-G65 -> 0 | H74: =G74+H73 -> 0 | I74: 0.003 | J74: =ROUND((D74*(I74)*H74)/E74,2) -> 0
G92: =G78 -> 0 | H92: =+H78 -> 0 | J92: =SUM(J74:J91) -> 0 | K92: =SUM(K74:K81) -> 0
B100: Emprunt - Facility agrement loan n°5
B101: Date de début de période | C101: Date de fin de période | D101: Durée | E101: Base | F101: Intitulé | G101: Mouvements | H101: Solde progressif | I101: marge | J101: Taux Euribor | K101: Intérêts | L101: Intérêt payé | M101: Intérêts courus
B103: 46006 | C103: 46022 | D103: =C103-B103 -> 16 | E103: 360 | F103: Tirage | G103: 57750000 | H103: =H102+G103 -> 57750000 | I103: 0.018 | J103: 0.02182 | K103: =ROUND((D103*(I103+J103)*H103)/E103,2) -> 102204.67 | M103: =K103+L103 -> 102204.67
G113: =SUM(G102:G112) -> 57750000 | K113: =SUM(K103:K112) -> 102204.67 | M113: =SUM(M103:M112) -> 102204.67
B115: Maturité | D115: 30/06/2026 (197 jours)
B116: intérêt au 30/06/2026 : | D116: 1258395
B117: Mage: | D117: 0.018
B118: Montant emprunté | D118: 57750000
B119: Emprunt - Commiment fee loan n°5
B120: Date de début de période | C120: Date de fin de période | D120: Durée | E120: Base | F120: Intitulé | G120: Mouvements | H120: Solde progressif | I120: Taux appliqué | J120: Intérêts | K120: Intérêts courus
B122: 46006 | C122: 46022 | D122: =C122-B122 -> 16 | E122: 360 | F122: Commission de non utilisation | G122: =D118-G113 -> 0 | H122: =G122+H121 -> 0 | I122: 0.003 | J122: =ROUND((D122*(I122)*H122)/E122,2) -> 0
...

Sheet Sous rachat
B1: =Sommaire!A1 -> BOLZEN - SLP | E1: Suivi des parts au | F1: =Sommaire!C1 -> 46022
B2: =Sommaire!B30 -> Euro
D4: Nature opération
B5: Nominal Parts A1 | C5: 1000 | D5: NP | E5: Transfert de Parts
B6: Nominal Parts A2 | C6: 1000 | D6: ADF | E6: Appel de fonds
B7: Nominal Parts Commandité | C7: 1000 | D7: DD | E7: Distribution définitive
D8: DB | E8: Distribition Bloquée
D9: DP | E9: Distribution provisoire
D10: RD | E10: Rappel de distribution
D11: ENG | E11: Engagement supplémentaire
